Workbook
Name Dienstag: #REF!
Name Donnerstag: #REF!
Name Freitag: #REF!
Name JP: #REF!
Name Mittwoch: #REF!
Name Montag: #REF!
Name Samstag: #REF!

Sheet Par (December 2025)
O1: 2025 | P1: 12 | R1: 1
C4: Article = เลิกใช้งาน | E4: Howler
C5: Article = ซ่อน สามารถใช้งานได้
F6: ซ่อน | G6: ซ่อน | H6: ซ่อน | I6: ซ่อน | O6: =+DATE($O$1,$P$1,$R$1) -> 45992 | AE6: Daily Cost | AH6: =+DATE($O$1,$P$1,$R$1)+1 -> 45993 | AX6: Daily Cost | BA6: =+DATE($O$1,$P$1,$R$1)+2 -> 45994 | BQ6: Daily Cost | BT6: =+DATE($O$1,$P$1,$R$1)+3 -> 45995 | CJ6: Daily Cost | CM6: =+DATE($O$1,$P$1,$R$1)+4 -> 45996 | DC6: Daily Cost | DF6: =+DATE($O$1,$P$1,$R$1)+5 -> 45997 | DV6: Daily Cost | DY6: =+DATE($O$1,$P$1,$R$1)+6 -> 45998 | EO6: Daily Cost | ER6: =+DATE($O$1,$P$1,$R$1)+7 -> 45999 | FH6: Daily Cost | FK6: =+DATE($O$1,$P$1,$R$1)+8 -> 46000 | GA6: Daily Cost | GD6: =+DATE($O$1,$P$1,$R$1)+9 -> 46001 | GT6: Daily Cost | GW6: =+DATE($O$1,$P$1,$R$1)+10 -> 46002 | HM6: Daily Cost | HP6: =+DATE($O$1,$P$1,$R$1)+11 -> 46003 | IF6: Daily Cost | II6: =+DATE($O$1,$P$1,$R$1)+12 -> 46004 | IY6: Daily Cost | JB6: =+DATE($O$1,$P$1,$R$1)+13 -> 46005 | JR6: Daily Cost | JU6: =+DATE($O$1,$P$1,$R$1)+14 -> 46006 | KK6: Daily Cost | KN6: =+DATE($O$1,$P$1,$R$1)+15 -> 46007 | LD6: Daily Cost | LG6: =+DATE($O$1,$P$1,$R$1)+16 -> 46008 | LW6: Daily Cost | LZ6: =+DATE($O$1,$P$1,$R$1)+17 -> 46009 | MP6: Daily Cost | MS6: =+DATE($O$1,$P$1,$R$1)+18 -> 46010 | NI6: Daily Cost | NL6: =+DATE($O$1,$P$1,$R$1)+19 -> 46011 | OB6: Daily Cost | OE6: =+DATE($O$1,$P$1,$R$1)+20 -> 46012 | OU6: Daily Cost | OX6: =+DATE($O$1,$P$1,$R$1)+21 -> 46013 | PN6: Daily Cost | PQ6: =+DATE($O$1,$P$1,$R$1)+22 -> 46014 | QG6: Daily Cost | QJ6: =+DATE($O$1,$P$1,$R$1)+23 -> 46015 | QZ6: Daily Cost | RA6: Full Check | RC6: =+DATE($O$1,$P$1,$R$1)+24 -> 46016 | RS6: Daily Cost | RV6: =+DATE($O$1,$P$1,$R$1)+25 -> 46017 | SL6: Daily Cost | SO6: =+DATE($O$1,$P$1,$R$1)+26 -> 46018 | TE6: Daily Cost | TH6: =+DATE($O$1,$P$1,$R$1)+27 -> 46019 | TX6: Daily Cost | UA6: =+DATE($O$1,$P$1,$R$1)+28 -> 46020 | UQ6: Daily Cost | UT6: =+DATE($O$1,$P$1,$R$1)+29 -> 46021 | VJ6: Daily Cost | VM6: =+DATE($O$1,$P$1,$R$1)+30 -> 46022 | WC6: Daily Cost | WG6: Par Summary of December 2025
C7: Master Line | D7: Alphabet Lin | E7: Description | F7: Par./ | H7: Par./ | J7: Supplier | K7: Unit | L7: Cost Per Unit | N7: Beginning Balance | O7: Open | P7: Store | Q7: Supplier | R7: T/F | T7: None-Selling | W7: Spoil | X7: Selling Btl. | Y7: Selling Shot | Z7: ช่องสูตร Gls. | AA7: Selling Cocktail ml. | AB7: ช่องสูตร Cocktail ml. | AC7: Balance Btl. | AD7: Balance Shot | AF7: Weekly Check | AG7: Diff | AH7: Open | AI7: Store | AJ7: Supplier | AK7: T/F | AM7: None-Selling | AP7: Spoil | AQ7: Selling Btl. | AR7: Selling Shot | AS7: ช่องสูตร Gls. | AT7: Selling Cocktail ml. | AU7: ช่องสูตร Cocktail ml. | AV7: Balance Btl. | AW7: Balance Shot | AY7: Weekly Check | AZ7: Diff | BA7: Open | BB7: Store | BC7: Supplier | BD7: T/F | BF7: None-Selling | BI7: Spoil | BJ7: Selling Btl. | BK7: Selling Shot | BL7: ช่องสูตร Gls. | BM7: Selling Cocktail ml. | BN7: ช่องสูตร Cocktail ml. | BO7: Balance Btl. | BP7: Balance Shot | BR7: Weekly Check | BS7: Diff | BT7: Open | BU7: Store | BV7: Supplier | BW7: T/F | BY7: None-Selling | CB7: Spoil | CC7: Selling Btl. | CD7: Selling Shot | CE7: ช่องสูตร Gls. | CF7: Selling Cocktail ml. | CG7: ช่องสูตร Cocktail ml. | CH7: Balance Btl. | CI7: Balance Shot | CK7: Weekly Check | CL7: Diff | CM7: Open | CN7: Store | CO7: Supplier | CP7: T/F | CR7: None-Selling | CU7: Spoil | CV7: Selling Btl. | CW7: Selling Shot | CX7: ช่องสูตร Gls. | CY7: Selling Cocktail ml. | CZ7: ช่องสูตร Cocktail ml. | DA7: Balance Btl. | DB7: Balance Shot | DD7: Weekly Check | DE7: Diff | DF7: Open | DG7: Store | DH7: Supplier | DI7: T/F | DK7: None-Selling | DN7: Spoil | DO7: Selling Btl. | DP7: Selling Shot | DQ7: ช่องสูตร Gls. | DR7: Selling Cocktail ml. | DS7: ช่องสูตร Cocktail ml. | DT7: Balance Btl. | DU7: Balance Shot | DW7: Weekly Check | DX7: Diff | DY7: Open | DZ7: Store | EA7: Supplier | EB7: T/F | ED7: None-Selling | EG7: Spoil | EH7: Selling Btl. | EI7: Selling Shot | EJ7: ช่องสูตร Gls. | EK7: Selling Cocktail ml. | EL7: ช่องสูตร Cocktail ml. | EM7: Balance Btl. | EN7: Balance Shot | EP7: Weekly Check | EQ7: Diff | ER7: Open | ES7: Store | ET7: Supplier | EU7: T/F | EW7: None-Selling | EZ7: Spoil | FA7: Selling Btl. | FB7: Selling Shot | FC7: ช่องสูตร Gls. | FD7: Selling Cocktail ml. | FE7: ช่องสูตร Cocktail ml. | FF7: Balance Btl. | FG7: Balance Shot | FI7: Weekly Check | FJ7: Diff | FK7: Open | FL7: Store | FM7: Supplier | FN7: T/F | FP7: None-Selling | FS7: Spoil | FT7: Selling Btl. | FU7: Selling Shot | FV7: ช่องสูตร Gls. | FW7: Selling Cocktail ml. | FX7: ช่องสูตร Cocktail ml. | FY7: Balance Btl. | FZ7: Balance Shot | GB7: Weekly Check | GC7: Diff | GD7: Open | GE7: Store | GF7: Supplier | GG7: T/F | GI7: None-Selling | GL7: Spoil | GM7: Selling Btl. | GN7: Selling Shot | GO7: ช่องสูตร Gls. | GP7: Selling Cocktail ml. | GQ7: ช่องสูตร Cocktail ml. | GR7: Balance Btl. | GS7: Balance Shot | GU7: Weekly Check | GV7: Diff | GW7: Open | GX7: Store | GY7: Supplier | GZ7: T/F | HB7: None-Selling | HE7: Spoil | HF7: Selling Btl. | HG7: Selling Shot | HH7: ช่องสูตร Gls. | HI7: Selling Cocktail ml. | HJ7: ช่องสูตร Cocktail ml. | HK7: Balance Btl. | HL7: Balance Shot | HN7: Weekly Check | HO7: Diff | HP7: Open | HQ7: Store | HR7: Supplier | HS7: T/F | HU7: None-Selling | HX7: Spoil | HY7: Selling Btl. | HZ7: Selling Shot | IA7: ช่องสูตร Gls. | IB7: Selling Cocktail ml. | IC7: ช่องสูตร Cocktail ml. | ID7: Balance Btl. | IE7: Balance Shot | IG7: Weekly Check | IH7: Diff | II7: Open | IJ7: Store | IK7: Supplier | IL7: T/F | IN7: None-Selling | IQ7: Spoil | IR7: Selling Btl. | IS7: Selling Shot | IT7: ช่องสูตร Gls. | IU7: Selling Cocktail ml. | IV7: ช่องสูตร Cocktail ml. | IW7: Balance Btl. | IX7: Balance Shot | IZ7: Weekly Check | JA7: Diff | JB7: Open | JC7: Store | JD7: Supplier | JE7: T/F | JG7: None-Selling | JJ7: Spoil | JK7: Selling Btl. | JL7: Selling Shot | JM7: ช่องสูตร Gls. | JN7: Selling Cocktail ml. | JO7: ช่องสูตร Cocktail ml. | JP7: Balance Btl. | JQ7: Balance Shot | JS7: Weekly Check | JT7: Diff | JU7: Open | JV7: Store | JW7: Supplier | JX7: T/F | JZ7: None-Selling | KC7: Spoil | KD7: Selling Btl. | KE7: Selling Shot | KF7: ช่องสูตร Gls. | KG7: Selling Cocktail ml. | KH7: ช่องสูตร Cocktail ml. | KI7: Balance Btl. | KJ7: Balance Shot | KL7: Weekly Check | KM7: Diff | KN7: Open | KO7: Store | KP7: Supplier | KQ7: T/F | KS7: None-Selling | KV7: Spoil | KW7: Selling Btl. | KX7: Selling Shot | KY7: ช่องสูตร Gls. | KZ7: Selling Cocktail ml. | LA7: ช่องสูตร Cocktail ml. | LB7: Balance Btl. | LC7: Balance Shot | LE7: Weekly Check | LF7: Diff | LG7: Open | LH7: Store | LI7: Supplier | LJ7: T/F | LL7: None-Selling | LO7: Spoil | LP7: Selling Btl. | LQ7: Selling Shot | LR7: ช่องสูตร Gls. | LS7: Selling Cocktail ml. | LT7: ช่องสูตร Cocktail ml. | LU7: Balance Btl. | LV7: Balance Shot | LX7: Weekly Check | LY7: Diff | LZ7: Open | MA7: Store | MB7: Supplier | MC7: T/F | ME7: None-Selling | MH7: Spoil | MI7: Selling Btl. | MJ7: Selling Shot | MK7: ช่องสูตร Gls. | ML7: Selling Cocktail ml. | MM7: ช่องสูตร Cocktail ml. | MN7: Balance Btl. | MO7: Balance Shot | MQ7: Weekly Check | MR7: Diff | MS7: Open | MT7: Store | MU7: Supplier | MV7: T/F | MX7: None-Selling | NA7: Spoil | NB7: Selling Btl. | NC7: Selling Shot | ND7: ช่องสูตร Gls. | NE7: Selling Cocktail ml. | NF7: ช่องสูตร Cocktail ml. | NG7: Balance Btl. | NH7: Balance Shot | NJ7: Weekly Check | NK7: Diff | NL7: Open | NM7: Store | NN7: Supplier | NO7: T/F | NQ7: None-Selling | NT7: Spoil | NU7: Selling Btl. | NV7: Selling Shot | NW7: ช่องสูตร Gls. | NX7: Selling Cocktail ml. | NY7: ช่องสูตร Cocktail ml. | NZ7: Balance Btl. | OA7: Balance Shot | OC7: Weekly Check | OD7: Diff | OE7: Open | OF7: Store | OG7: Supplier | OH7: T/F | OJ7: None-Selling | OM7: Spoil | ON7: Selling Btl. | OO7: Selling Shot | OP7: ช่องสูตร Gls. | OQ7: Selling Cocktail ml. | OR7: ช่องสูตร Cocktail ml. | OS7: Balance Btl. | OT7: Balance Shot | OV7: Weekly Check | OW7: Diff | OX7: Open | OY7: Store | OZ7: Supplier | PA7: T/F | PC7: None-Selling | PF7: Spoil | PG7: Selling Btl. | PH7: Selling Shot | PI7: ช่องสูตร Gls. | PJ7: Selling Cocktail ml. | PK7: ช่องสูตร Cocktail ml. | PL7: Balance Btl. | PM7: Balance Shot | PO7: Weekly Check | PP7: Diff | PQ7: Open | PR7: Store | PS7: Supplier | PT7: T/F | PV7: None-Selling | PY7: Spoil | PZ7: Selling Btl. | QA7: Selling Shot | QB7: ช่องสูตร Gls. | QC7: Selling Cocktail ml. | QD7: ช่องสูตร Cocktail ml. | QE7: Balance Btl. | QF7: Balance Shot | QH7: Weekly Check | QI7: Diff | QJ7: Open | QK7: Store | QL7: Supplier | QM7: T/F | QO7: None-Selling | QR7: Spoil | QS7: Selling Btl. | QT7: Selling Shot | QU7: ช่องสูตร Gls. | QV7: Selling Cocktail ml. | QW7: ช่องสูตร Cocktail ml. | QX7: Balance Btl. | QY7: Balance Shot | RA7: Check | RB7: Diff | RC7: Open | RD7: Store | RE7: Supplier | RF7: T/F | RH7: None-Selling | RK7: Spoil | RL7: Selling Btl. | RM7: Selling Shot | RN7: ช่องสูตร Gls. | RO7: Selling Cocktail ml. | RP7: ช่องสูตร Cocktail ml. | RQ7: Balance Btl. | RR7: Balance Shot | RT7: Weekly Check | RU7: Diff | RV7: Open | RW7: Store | RX7: Supplier | RY7: T/F | SA7: None-Selling | SD7: Spoil | SE7: Selling Btl. | SF7: Selling Shot | SG7: ช่องสูตร Gls. | SH7: Selling Cocktail ml. | SI7: ช่องสูตร Cocktail ml. | SJ7: Balance Btl. | SK7: Balance Shot | SM7: Weekly Check | SN7: Diff | SO7: Open | SP7: Store | SQ7: Supplier | SR7: T/F | ST7: None-Selling | SW7: Spoil | SX7: Selling Btl. | SY7: Selling Shot | SZ7: ช่องสูตร Gls. | TA7: Selling Cocktail ml. | TB7: ช่องสูตร Cocktail ml. | TC7: Balance Btl. | TD7: Balance Shot | TF7: Weekly Check | TG7: Diff | TH7: Open | TI7: Store | TJ7: Supplier | TK7: T/F | TM7: None-Selling | TP7: Spoil | TQ7: Selling Btl. | TR7: Selling Shot | TS7: ช่องสูตร Gls. | TT7: Selling Cocktail ml. | TU7: ช่องสูตร Cocktail ml. | TV7: Balance Btl. | TW7: Balance Shot | TY7: Weekly Check | TZ7: Diff | UA7: Open | UB7: Store | UC7: Supplier | UD7: T/F | UF7: None-Selling | UI7: Spoil | UJ7: Selling Btl. | UK7: Selling Shot | UL7: ช่องสูตร Gls. | UM7: Selling Cocktail ml. | UN7: ช่องสูตร Cocktail ml. | UO7: Balance Btl. | UP7: Balance Shot | UR7: Weekly Check | US7: Diff | UT7: Open | UU7: Store | UV7: Supplier | UW7: T/F | UY7: None-Selling | VB7: Spoil | VC7: Selling Btl. | VD7: Selling Shot | VE7: ช่องสูตร Gls. | VF7: Selling Cocktail ml. | VG7: ช่องสูตร Cocktail ml. | VH7: Balance Btl. | VI7: Balance Shot | VK7: Weekly Check | VL7: Diff | VM7: Open | VN7: Store | VO7: Supplier | VP7: T/F | VR7: None-Selling | VU7: Spoil | VV7: Selling Btl. | VW7: Selling Shot | VX7: ช่องสูตร Gls. | VY7: Selling Cocktail ml. | VZ7: ช่องสูตร Cocktail ml. | WA7: Balance Btl. | WB7: Balance Shot | WD7: Weekly Check | WE7: Diff | WG7: OPEN | WH7: Store | WI7: Supplier | WJ7: T/F IN | WK7: T/F OUT | WL7: ENT. | WM7: OC | WN7: Mixer | WO7: Spoil | WP7: Selling Btl. | WQ7: Selling Shot | WR7: Selling ml./Shot Sum To Btl. | WS7: Selling cocktail Sum to Btl. | WT7: CLOSING Balance Btl. | WU7: CLOSING Balance Shot | WV7: Actaul Inventory | WW7: Diff | WX7: Key MC
F8: Oz. | H8: ml. | L8: Btl. | M8: Shot | R8: In | S8: Out | T8: Ent. | U8: OC | V8: Mixer | AK8: In | AL8: Out | AM8: Ent. | AN8: OC | AO8: Mixer | BD8: In | BE8: Out | BF8: Ent. | BG8: OC | BH8: Mixer | BW8: In | BX8: Out | BY8: Ent. | BZ8: OC | CA8: Mixer | CP8: In | CQ8: Out | CR8: Ent. | CS8: OC | CT8: Mixer | DI8: In | DJ8: Out | DK8: Ent. | DL8: OC | DM8: Mixer | EB8: In | EC8: Out | ED8: Ent. | EE8: OC | EF8: Mixer | EU8: In | EV8: Out | EW8: Ent. | EX8: OC | EY8: Mixer | FN8: In | FO8: Out | FP8: Ent. | FQ8: OC | FR8: Mixer | GG8: In | GH8: Out | GI8: Ent. | GJ8: OC | GK8: Mixer | GZ8: In | HA8: Out | HB8: Ent. | HC8: OC | HD8: Mixer | HS8: In | HT8: Out | HU8: Ent. | HV8: OC | HW8: Mixer | IL8: In | IM8: Out | IN8: Ent. | IO8: OC | IP8: Mixer | JE8: In | JF8: Out | JG8: Ent. | JH8: OC | JI8: Mixer | JX8: In | JY8: Out | JZ8: Ent. | KA8: OC | KB8: Mixer | KQ8: In | KR8: Out | KS8: Ent. | KT8: OC | KU8: Mixer | LJ8: In | LK8: Out | LL8: Ent. | LM8: OC | LN8: Mixer | MC8: In | MD8: Out | ME8: Ent. | MF8: OC | MG8: Mixer | MV8: In | MW8: Out | MX8: Ent. | MY8: OC | MZ8: Mixer | NO8: In | NP8: Out | NQ8: Ent. | NR8: OC | NS8: Mixer | OH8: In | OI8: Out | OJ8: Ent. | OK8: OC | OL8: Mixer | PA8: In | PB8: Out | PC8: Ent. | PD8: OC | PE8: Mixer | PT8: In | PU8: Out | PV8: Ent. | PW8: OC | PX8: Mixer | QM8: In | QN8: Out | QO8: Ent. | QP8: OC | QQ8: Mixer | RF8: In | RG8: Out | RH8: Ent. | RI8: OC | RJ8: Mixer | RY8: In | RZ8: Out | SA8: Ent. | SB8: OC | SC8: Mixer | SR8: In | SS8: Out | ST8: Ent. | SU8: OC | SV8: Mixer | TK8: In | TL8: Out | TM8: Ent. | TN8: OC | TO8: Mixer | UD8: In | UE8: Out | UF8: Ent. | UG8: OC | UH8: Mixer | UW8: In | UX8: Out | UY8: Ent. | UZ8: OC | VA8: Mixer | VP8: In | VQ8: Out | VR8: Ent. | VS8: OC | VT8: Mixer
A9: =IFERROR(IF(WU9=0,"-","Y"),"-") -> - | C9: 23 | D9: 1 | E9: Blended Scotch Whisky
A10: =IFERROR(IF(WU10=0,"-","Y"),"-") -> - | C10: 24 | D10: 2 | E10: JW Black Label 700 ml | F10: =IF(E10="","",IF(VLOOKUP(E10,'Master Data (December 2025)'!$B$10:$N$857,1)=E10,VLOOKUP(E10,'Master Data (December 2025)'!$B$10:$N$857,6),"XX")) -> 1 | H10: =IF(E10="","",IF(VLOOKUP(E10,'Master Data (December 2025)'!$B$10:$N$857,1)=E10,VLOOKUP(E10,'Master Data (December 2025)'!$B$10:$N$857,8),"XX")) -> 22 | J10: =IF(E10="","",IF(VLOOKUP(E10,'Master Data (December 2025)'!$B$10:$N$857,1)=E10,VLOOKUP(E10,'Master Data (December 2025)'!$B$10:$N$857,3),"XX")) -> สมภพ,อมฤต | K10: =IF(E10="","",IF(VLOOKUP(E10,'Master Data (December 2025)'!$B$10:$N$857,1)=E10,VLOOKUP(E10,'Master Data (December 2025)'!$B$10:$N$857,5),"XX")) -> Btl 700 ml | L10: =IF(E10="","",IF(VLOOKUP(E10,'Master Data (December 2025)'!$B$10:$N$857,1)=E10,VLOOKUP(E10,'Master Data (December 2025)'!$B$10:$N$857,11),"XX")) -> 1392 | M10: =IF(E10="","",IF(VLOOKUP(E10,'Master Data (December 2025)'!$B$10:$N$857,1)=E10,VLOOKUP(E10,'Master Data (December 2025)'!$B$10:$N$857,13),"XX")) -> 63.272727 | O10: =N10 -> 0 | Z10: =(Y10*F10)/H10 -> 0 | AA10: =IF(E10=0,0,SUMIF('Cocktail (December 2025)'!$F$6:$DB$1547,E10,'Cocktail (December 2025)'!$O$6:$O$1547)) -> 0 | AB10: =AA10/H10 -> 0 | AC10: =O10+P10+Q10+R10-S10-T10-U10-V10-W10-X10-Z10-AB10 -> 0 | AD10: =AC10*H10 -> 0 | AE10: =(T10+U10+V10+W10+(X10+((Y10*$F10)/$H10)+AB10))*$L10 -> 0 | AG10: =AF10-AC10 -> 0 | AH10: =IF(AF10="",AC10,IF(AF10<>0,AF10,0)) -> 0 | AS10: =(AR10*F10)/H10 -> 0 | AT10: =IF(E10=0,0,SUMIF('Cocktail (December 2025)'!$F$6:$DB$1547,E10,'Cocktail (December 2025)'!$R$6:$R$1547)) -> 0 | AU10: =AT10/H10 -> 0 | AV10: =AH10+AI10+AJ10+AK10-AL10-AM10-AN10-AO10-AP10-AQ10-AS10-AU10 -> 0 | AW10: =AV10*H10 -> 0 | AX10: =(AM10+AN10+AO10+AP10+(AQ10+((AR10*$F10)/$H10)+AU10))*$L10 -> 0 | AZ10: =AY10-AV10 -> 0 | BA10: =AV10 -> 0 | BL10: =(BK10*F10)/H10 -> 0 | BM10: =IF(E10=0,0,SUMIF('Cocktail (December 2025)'!$F$6:$DB$1547,E10,'Cocktail (December 2025)'!$U$6:$U$1547)) -> 0 | BN10: =BM10/H10 -> 0 | BO10: =BA10+BB10+BC10+BD10-BE10-BF10-BG10-BH10-BI10-BJ10-BL10-BN10 -> 0 | BP10: =BO10*H10 -> 0 | BQ10: =(BF10+BG10+BH10+BI10+(BJ10+((BK10*$F10)/$H10)+BN10))*$L10 -> 0 | BS10: =BR10-BO10 -> 0 | BT10: =BO10 -> 0 | CE10: =(CD10*F10)/H10 -> 0 | CF10: =IF(E10=0,0,SUMIF('Cocktail (December 2025)'!$F$6:$DB$1547,E10,'Cocktail (December 2025)'!$X$6:$X$1547)) -> 0 | CG10: =CF10/H10 -> 0 | CH10: =BT10+BU10+BV10+BW10-BX10-BY10-BZ10-CA10-CB10-CC10-CE10-CG10 -> 0 | CI10: =CH10*H10 -> 0 | CJ10: =(BY10+BZ10+CA10+CB10+(CC10+((CD10*$F10)/$H10)+CG10))*$L10 -> 0 | CL10: =CK10-CH10 -> 0 | CM10: =CH10 -> 0 | CX10: =(CW10*F10)/H10 -> 0 | CY10: =IF(E10=0,0,SUMIF('Cocktail (December 2025)'!$F$6:$DB$1547,E10,'Cocktail (December 2025)'!$AA$6:$AA$1547)) -> 0 | CZ10: =CY10/H10 -> 0 | DA10: =CM10+CN10+CO10+CP10-CQ10-CR10-CS10-CT10-CU10-CV10-CX10-CZ10 -> 0 | DB10: =DA10*H10 -> 0 | DC10: =(CR10+CS10+CT10+CU10+(CV10+((CW10*$F10)/$H10)+CZ10))*$L10 -> 0 | DE10: =DD10-DA10 -> 0 | DF10: =DA10 -> 0 | DQ10: =(DP10*F10)/H10 -> 0 | DR10: =IF(E10=0,0,SUMIF('Cocktail (December 2025)'!$F$6:$DB$1547,E10,'Cocktail (December 2025)'!$AD$6:$AD$1547)) -> 0 | DS10: =DR10/H10 -> 0 | DT10: =DF10+DG10+DH10+DI10-DJ10-DK10-DL10-DM10-DN10-DO10-DQ10-DS10 -> 0 | DU10: =DT10*H10 -> 0 | DV10: =(DK10+DL10+DM10+DN10+(DO10+((DP10*$F10)/$H10)+DS10))*$L10 -> 0 | DX10: =DW10-DT10 -> 0 | DY10: =DT10 -> 0 | EJ10: =(EI10*F10)/H10 -> 0 | EK10: =IF(E10=0,0,SUMIF('Cocktail (December 2025)'!$F$6:$DB$1547,E10,'Cocktail (December 2025)'!$AG$6:$AG$1547)) -> 0 | EL10: =EK10/H10 -> 0 | EM10: =DY10+DZ10+EA10+EB10-EC10-ED10-EE10-EF10-EG10-EH10-EJ10-EL10 -> 0 | EN10: =EM10*H10 -> 0 | EO10: =(ED10+EE10+EF10+EG10+(EH10+((EI10*$F10)/$H10)+EL10))*$L10 -> 0 | EQ10: =EP10-EM10 -> 0 | ER10: =EM10 -> 0 | FC10: =(FB10*F10)/H10 -> 0 | FD10: =IF(E10=0,0,SUMIF('Cocktail (December 2025)'!$F$6:$DB$1547,E10,'Cocktail (December 2025)'!$AJ$6:$AJ$1547)) -> 0 | FE10: =FD10/H10 -> 0 | FF10: =ER10+ES10+ET10+EU10-EV10-EW10-EX10-EY10-EZ10-FA10-FC10-FE10 -> 0 | FG10: =FF10*H10 -> 0 | FH10: =(EW10+EX10+EY10+EZ10+(FA10+((FB10*$F10)/$H10)+FE10))*$L10 -> 0 | FJ10: =FI10-FF10 -> 0 | FK10: =FF10 -> 0 | FV10: =(FU10*F10)/H10 -> 0 | FW10: =IF(E10=0,0,SUMIF('Cocktail (December 2025)'!$F$6:$DB$1547,E10,'Cocktail (December 2025)'!$AM$6:$AM$1547)) -> 0 | FX10: =FW10/H10 -> 0 | FY10: =FK10+FL10+FM10+FN10-FO10-FP10-FQ10-FR10-FS10-FT10-FV10-FX10 -> 0 | FZ10: =FY10*H10 -> 0 | GA10: =(FP10+FQ10+FR10+FS10+(FT10+((FU10*$F10)/$H10)+FX10))*$L10 -> 0 | GC10: =GB10-FY10 -> 0 | GD10: =FY10 -> 0 | GO10: =(GN10*F10)/H10 -> 0 | GP10: =IF(E10=0,0,SUMIF('Cocktail (December 2025)'!$F$6:$DB$1547,E10,'Cocktail (December 2025)'!$AP$6:$AP$1547)) -> 0 | GQ10: =GP10/H10 -> 0 | GR10: =GD10+GE10+GF10+GG10-GH10-GI10-GJ10-GK10-GL10-GM10-GO10-GQ10 -> 0 | GS10: =GR10*H10 -> 0 | GT10: =(GI10+GJ10+GK10+GL10+(GM10+((GN10*$F10)/$H10)+GQ10))*$L10 -> 0 | GV10: =GU10-GR10 -> 0 | GW10: =GR10 -> 0 | HH10: =(HG10*F10)/H10 -> 0 | HI10: =IF(E10=0,0,SUMIF('Cocktail (December 2025)'!$F$6:$DB$1547,E10,'Cocktail (December 2025)'!$AS$6:$AS$1547)) -> 0 | HJ10: =HI10/H10 -> 0 | HK10: =GW10+GX10+GY10+GZ10-HA10-HB10-HC10-HD10-HE10-HF10-HH10-HJ10 -> 0 | HL10: =HK10*H10 -> 0 | HM10: =(HB10+HC10+HD10+HE10+(HF10+((HG10*$F10)/$H10)+HJ10))*$L10 -> 0 | HO10: =HN10-HK10 -> 0 | HP10: =HK10 -> 0 | IA10: =(HZ10*F10)/H10 -> 0 | IB10: =IF(E10=0,0,SUMIF('Cocktail (December 2025)'!$F$6:$DB$1547,E10,'Cocktail (December 2025)'!$AV$6:$AV$1547)) -> 0 | IC10: =IB10/H10 -> 0 | ID10: =HP10+HQ10+HR10+HS10-HT10-HU10-HV10-HW10-HX10-HY10-IA10-IC10 -> 0 | IE10: =ID10*H10 -> 0 | IF10: =(HU10+HV10+HW10+HX10+(HY10+((HZ10*$F10)/$H10)+IC10))*$L10 -> 0 | IH10: =IG10-ID10 -> 0 | II10: =ID10 -> 0 | IT10: =(IS10*F10)/H10 -> 0 | IU10: =IF(E10=0,0,SUMIF('Cocktail (December 2025)'!$F$6:$DB$1547,E10,'Cocktail (December 2025)'!$AY$6:$AY$1547)) -> 0 | IV10: =IU10/H10 -> 0 | IW10: =II10+IJ10+IK10+IL10-IM10-IN10-IO10-IP10-IQ10-IR10-IT10-IV10 -> 0 | IX10: =IW10*H10 -> 0 | IY10: =(IN10+IO10+IP10+IQ10+(IR10+((IS10*$F10)/$H10)+IV10))*$L10 -> 0 | JA10: =IZ10-IW10 -> 0 | JB10: =IW10 -> 0 | JM10: =(JL10*F10)/H10 -> 0 | JN10: =IF(E10=0,0,SUMIF('Cocktail (December 2025)'!$F$6:$DB$1547,E10,'Cocktail (December 2025)'!$BB$6:$BB$1547)) -> 0 | JO10: =JN10/H10 -> 0 | JP10: =JB10+JC10+JD10+JE10-JF10-JG10-JH10-JI10-JJ10-JK10-JM10-JO10 -> 0 | JQ10: =JP10*H10 -> 0 | JR10: =(JG10+JH10+JI10+JJ10+(JK10+((JL10*$F10)/$H10)+JO10))*$L10 -> 0 | JT10: =JS10-JP10 -> 0 | JU10: =JP10 -> 0 | KF10: =(KE10*F10)/H10 -> 0 | KG10: =IF(E10=0,0,SUMIF('Cocktail (December 2025)'!$F$6:$DB$1547,E10,'Cocktail (December 2025)'!$BE$6:$BE$1547)) -> 0 | KH10: =KG10/H10 -> 0 | KI10: =JU10+JV10+JW10+JX10-JY10-JZ10-KA10-KB10-KC10-KD10-KF10-KH10 -> 0 | KJ10: =KI10*H10 -> 0 | KK10: =(JZ10+KA10+KB10+KC10+(KD10+((KE10*$F10)/$H10)+KH10))*$L10 -> 0 | KM10: =KL10-KI10 -> 0 | KN10: =KI10 -> 0 | KY10: =(KX10*F10)/H10 -> 0 | KZ10: =IF(E10=0,0,SUMIF('Cocktail (December 2025)'!$F$6:$DB$1547,E10,'Cocktail (December 2025)'!$BH$6:$BH$1547)) -> 0 | LA10: =KZ10/H10 -> 0 | LB10: =KN10+KO10+KP10+KQ10-KR10-KS10-KT10-KU10-KV10-KW10-KY10-LA10 -> 0 | LC10: =LB10*H10 -> 0 | LD10: =(KS10+KT10+KU10+KV10+(KW10+((KX10*$F10)/$H10)+LA10))*$L10 -> 0 | LF10: =LE10-LB10 -> 0 | LG10: =LB10 -> 0 | LR10: =(LQ10*F10)/H10 -> 0 | LS10: =IF(E10=0,0,SUMIF('Cocktail (December 2025)'!$F$6:$DB$1547,E10,'Cocktail (December 2025)'!$BK$6:$BK$1547)) -> 0 | LT10: =LS10/H10 -> 0 | LU10: =LG10+LH10+LI10+LJ10-LK10-LL10-LM10-LN10-LO10-LP10-LR10-LT10 -> 0 | LV10: =LU10*H10 -> 0 | LW10: =(LL10+LM10+LN10+LO10+(LP10+((LQ10*$F10)/$H10)+LT10))*$L10 -> 0 | LY10: =LX10-LU10 -> 0 | LZ10: =LU10 -> 0 | MK10: =(MJ10*F10)/H10 -> 0 | ML10: =IF(E10=0,0,SUMIF('Cocktail (December 2025)'!$F$6:$DB$1547,E10,'Cocktail (December 2025)'!$BN$6:$BN$1547)) -> 0 | MM10: =ML10/H10 -> 0 | MN10: =LZ10+MA10+MB10+MC10-MD10-ME10-MF10-MG10-MH10-MI10-MK10-MM10 -> 0 | MO10: =MN10*H10 -> 0 | MP10: =(ME10+MF10+MG10+MH10+(MI10+((MJ10*$F10)/$H10)+MM10))*$L10 -> 0 | MR10: =MQ10-MN10 -> 0 | MS10: =MN10 -> 0 | ND10: =(NC10*F10)/H10 -> 0 | NE10: =IF(E10=0,0,SUMIF('Cocktail (December 2025)'!$F$6:$DB$1547,E10,'Cocktail (December 2025)'!$BQ$6:$BQ$1547)) -> 0 | NF10: =NE10/H10 -> 0 | NG10: =MS10+MT10+MU10+MV10-MW10-MX10-MY10-MZ10-NA10-NB10-ND10-NF10 -> 0 | NH10: =NG10*H10 -> 0 | NI10: =(MX10+MY10+MZ10+NA10+(NB10+((NC10*$F10)/$H10)+NF10))*$L10 -> 0 | NK10: =NJ10-NG10 -> 0 | NL10: =NG10 -> 0 | NW10: =(NV10*F10)/H10 -> 0 | NX10: =IF(E10=0,0,SUMIF('Cocktail (December 2025)'!$F$6:$DB$1547,E10,'Cocktail (December 2025)'!$BT$6:$BT$1547)) -> 0 | NY10: =NX10/H10 -> 0 | NZ10: =NL10+NM10+NN10+NO10-NP10-NQ10-NR10-NS10-NT10-NU10-NW10-NY10 -> 0 | OA10: =NZ10*H10 -> 0 | OB10: =(NQ10+NR10+NS10+NT10+(NU10+((NV10*$F10)/$H10)+NY10))*$L10 -> 0 | OD10: =OC10-NZ10 -> 0 | OE10: =NZ10 -> 0 | OP10: =(OO10*F10)/H10 -> 0 | OQ10: =IF(E10=0,0,SUMIF('Cocktail (December 2025)'!$F$6:$DB$1547,E10,'Cocktail (December 2025)'!$BW$6:$BW$1547)) -> 0 | OR10: =OQ10/H10 -> 0 | OS10: =OE10+OF10+OG10+OH10-OI10-OJ10-OK10-OL10-OM10-ON10-OP10-OR10 -> 0 | OT10: =OS10*H10 -> 0 | OU10: =(OJ10+OK10+OL10+OM10+(ON10+((OO10*$F10)/$H10)+OR10))*$L10 -> 0 | OW10: =OV10-OS10 -> 0 | OX10: =OS10 -> 0 | PI10: =(PH10*F10)/H10 -> 0 | PJ10: =IF(E10=0,0,SUMIF('Cocktail (December 2025)'!$F$6:$DB$1547,E10,'Cocktail (December 2025)'!$BZ$6:$BZ$1547)) -> 0 | PK10: =PJ10/H10 -> 0 | PL10: =OX10+OY10+OZ10+PA10-PB10-PC10-PD10-PE10-PF10-PG10-PI10-PK10 -> 0 | PM10: =PL10*H10 -> 0 | PN10: =(PC10+PD10+PE10+PF10+(PG10+((PH10*$F10)/$H10)+PK10))*$L10 -> 0 | PP10: =PO10-PL10 -> 0 | PQ10: =PL10 -> 0 | QB10: =(QA10*F10)/H10 -> 0 | QC10: =IF(E10=0,0,SUMIF('Cocktail (December 2025)'!$F$6:$DB$1547,E10,'Cocktail (December 2025)'!$CC$6:$CC$1547)) -> 0 | QD10: =QC10/H10 -> 0 | QE10: =PQ10+PR10+PS10+PT10-PU10-PV10-PW10-PX10-PY10-PZ10-QB10-QD10 -> 0 | QF10: =QE10*H10 -> 0 | QG10: =(PV10+PW10+PX10+PY10+(PZ10+((QA10*$F10)/$H10)+QD10))*$L10 -> 0 | QI10: =QH10-QE10 -> 0 | QJ10: =QE10 -> 0 | QU10: =(QT10*F10)/H10 -> 0 | QV10: =IF(E10=0,0,SUMIF('Cocktail (December 2025)'!$F$6:$DB$1547,E10,'Cocktail (December 2025)'!$CF$6:$CF$1547)) -> 0 | QW10: =QV10/H10 -> 0 | QX10: =QJ10+QK10+QL10+QM10-QN10-QO10-QP10-QQ10-QR10-QS10-QU10-QW10 -> 0 | QY10: =QX10*H10 -> 0 | QZ10: =(QO10+QP10+QQ10+QR10+(QS10+((QT10*$F10)/$H10)+QW10))*$L10 -> 0 | RB10: =RA10-QX10 -> 0 | RC10: =QX10 -> 0 | RN10: =(RM10*F10)/H10 -> 0 | RO10: =IF(E10=0,0,SUMIF('Cocktail (December 2025)'!$F$6:$DB$1547,E10,'Cocktail (December 2025)'!$CI$6:$CI$1547)) -> 0 | RP10: =RO10/H10 -> 0 | RQ10: =RC10+RD10+RE10+RF10-RG10-RH10-RI10-RJ10-RK10-RL10-RN10-RP10 -> 0 | RR10: =RQ10*H10 -> 0 | RS10: =(RH10+RI10+RJ10+RK10+(RL10+((RM10*$F10)/$H10)+RP10))*$L10 -> 0 | RU10: =RT10-RQ10 -> 0 | RV10: =RQ10 -> 0 | SG10: =(SF10*F10)/H10 -> 0 | SH10: =IF(E10=0,0,SUMIF('Cocktail (December 2025)'!$F$6:$DB$1547,E10,'Cocktail (December 2025)'!$CL$6:$CL$1547)) -> 0 | SI10: =SH10/H10 -> 0 | SJ10: =RV10+RW10+RX10+RY10-RZ10-SA10-SB10-SC10-SD10-SE10-SG10-SI10 -> 0 | SK10: =SJ10*H10 -> 0 | SL10: =(SA10+SB10+SC10+SD10+(SE10+((SF10*$F10)/$H10)+SI10))*$L10 -> 0 | SN10: =SM10-SJ10 -> 0 | SO10: =SJ10 -> 0 | SZ10: =(SY10*F10)/H10 -> 0 | TA10: =IF(E10=0,0,SUMIF('Cocktail (December 2025)'!$F$6:$DB$1547,E10,'Cocktail (December 2025)'!$CO$6:$CO$1547)) -> 0 | TB10: =TA10/H10 -> 0 | TC10: =SO10+SP10+SQ10+SR10-SS10-ST10-SU10-SV10-SW10-SX10-SZ10-TB10 -> 0 | TD10: =TC10*H10 -> 0 | TE10: =(ST10+SU10+SV10+SW10+(SX10+((SY10*$F10)/$H10)+TB10))*$L10 -> 0 | TG10: =TF10-TC10 -> 0 | TH10: =TC10 -> 0 | TS10: =(TR10*F10)/H10 -> 0 | TT10: =IF(E10=0,0,SUMIF('Cocktail (December 2025)'!$F$6:$DB$1547,E10,'Cocktail (December 2025)'!$CR$6:$CR$1547)) -> 0 | TU10: =TT10/H10 -> 0 | TV10: =TH10+TI10+TJ10+TK10-TL10-TM10-TN10-TO10-TP10-TQ10-TS10-TU10 -> 0 | TW10: =TV10*H10 -> 0 | TX10: =(TM10+TN10+TO10+TP10+(TQ10+((TR10*$F10)/$H10)+TU10))*$L10 -> 0 | TZ10: =TY10-TV10 -> 0 | UA10: =TV10 -> 0 | UL10: =(UK10*F10)/H10 -> 0 | UM10: =IF(E10=0,0,SUMIF('Cocktail (December 2025)'!$F$6:$DB$1547,E10,'Cocktail (December 2025)'!$CU$6:$CU$1547)) -> 0 | UN10: =UM10/H10 -> 0 | UO10: =UA10+UB10+UC10+UD10-UE10-UF10-UG10-UH10-UI10-UJ10-UL10-UN10 -> 0 | UP10: =UO10*H10 -> 0 | UQ10: =(UF10+UG10+UH10+UI10+(UJ10+((UK10*$F10)/$H10)+UN10))*$L10 -> 0 | US10: =UR10-UO10 -> 0 | UT10: =UO10 -> 0 | VE10: =(VD10*F10)/H10 -> 0 | VF10: =IF(E10=0,0,SUMIF('Cocktail (December 2025)'!$F$6:$DB$1547,E10,'Cocktail (December 2025)'!$CX$6:$CX$1547)) -> 0 | VG10: =VF10/H10 -> 0 | VH10: =UT10+UU10+UV10+UW10-UX10-UY10-UZ10-VA10-VB10-VC10-VE10-VG10 -> 0 | VI10: =VH10*H10 -> 0 | VJ10: =(UY10+UZ10+VA10+VB10+(VC10+((VD10*$F10)/$H10)+VG10))*$L10 -> 0 | VL10: =VK10-VH10 -> 0 | VM10: =VH10 -> 0 | VX10: =(VW10*F10)/H10 -> 0 | VY10: =IF(E10=0,0,SUMIF('Cocktail (December 2025)'!$F$6:$DB$1547,E10,'Cocktail (December 2025)'!$DA$6:$DA$1547)) -> 0 | VZ10: =VY10/H10 -> 0 | WA10: =VM10+VN10+VO10+VP10-VQ10-VR10-VS10-VT10-VU10-VV10-VX10-VZ10 -> 0 | WB10: =WA10*H10 -> 0 | WC10: =(VR10+VS10+VT10+VU10+(VV10+((VW10*$F10)/$H10)+VZ10))*$L10 -> 0 | WE10: =WD10-WA10 -> 0 | WF10: X | WG10: =O10 -> 0 | WH10: =P10+AI10+BB10+BU10+CN10+DG10+DZ10+ES10+FL10+GE10+GX10+HQ10+IJ10+JC10+JV10+KO10+LH10+MA10+MT10+NM10+OF10+OY10+PR10+QK10+RD10+RW10+SP10+TI10+UB10+UU10+VN10 -> 0 | WI10: =Q10+AJ10+BC10+BV10+CO10+DH10+EA10+ET10+FM10+GF10+GY10+HR10+IK10+JD10+JW10+KP10+LI10+MB10+MU10+NN10+OG10+OZ10+PS10+QL10+RE10+RX10+SQ10+TJ10+UC10+UV10+VO10 -> 0 | WJ10: =R10+AK10+BD10+BW10+CP10+DI10+EB10+EU10+FN10+GG10+GZ10+HS10+IL10+JE10+JX10+KQ10+LJ10+MC10+MV10+NO10+OH10+PA10+PT10+QM10+RF10+RY10+SR10+TK10+UD10+UW10+VP10 -> 0 | WK10: =S10+AL10+BE10+BX10+CQ10+DJ10+EC10+EV10+FO10+GH10+HA10+HT10+IM10+JF10+JY10+KR10+LK10+MD10+MW10+NP10+OI10+PB10+PU10+QN10+RG10+RZ10+SS10+TL10+UE10+UX10+VQ10 -> 0 | WL10: =T10+AM10+BF10+BY10+CR10+DK10+ED10+EW10+FP10+GI10+HB10+HU10+IN10+JG10+JZ10+KS10+LL10+ME10+MX10+NQ10+OJ10+PC10+PV10+QO10+RH10+SA10+ST10+TM10+UF10+UY10+VR10 -> 0 | WM10: =U10+AN10+BG10+BZ10+CS10+DL10+EE10++EX10+FQ10+GJ10+HC10+HV10+IO10+JH10+KA10+KT10+LM10+MF10+MY10+NR10+OK10+PD10+PW10+QP10+RI10+SB10+SU10+TN10+UG10+UZ10+VS10 -> 0 | WN10: =V10+AO10+BH10+CA10+CT10+DM10+EF10+EY10+FR10+GK10+HD10+HW10+IP10+JI10+KB10+KU10+LN10+MG10+MZ10+NS10+OL10+PE10+PX10+QQ10+RJ10+SC10+SV10+TO10+UH10+VA10+VT10 -> 0 | WO10: =W10+AP10+BI10+CB10+CU10+DN10+EG10+EZ10+FS10+GL10+HE10+HX10+IQ10+JJ10+KC10+KV10+LO10+MH10+NA10+NT10+OM10+PF10+PY10+QR10+RK10+SD10+SW10+TP10+UI10+VB10+VU10 -> 0 | WP10: =X10+AQ10+BJ10+CC10+CV10+DO10+EH10+FA10+FT10+GM10+HF10+HY10+IR10+JK10+KD10+KW10+LP10+MI10+NB10+NU10+ON10+PG10+PZ10+QS10+RL10+SE10+SX10+TQ10+UJ10+VC10+VV10 -> 0 | WQ10: =Y10+AR10+BK10+CD10+CW10+DP10+EI10+FB10+FU10+GN10+HG10+HZ10+IS10+JL10+KE10+KX10+LQ10+MJ10+NC10+NV10+OO10+PH10+QA10+QT10+RM10+SF10+SY10+TR10+UK10+VD10+VW10 -> 0 | WR10: =Z10+AS10+BL10+CE10+CX10+DQ10+EJ10+FC10+FV10+GO10+HH10+IA10+IT10+JM10+KF10+KY10+LR10+MK10+ND10+NW10+OP10+PI10+QB10+QU10+RN10+SG10+SZ10+TS10+UL10+VE10+VX10 -> 0 | WS10: =AB10+AU10+BN10+CG10+CZ10+DS10+EL10+FE10+FX10+GQ10+HJ10+IC10+IV10+JO10+KH10+LA10+LT10+MM10+NF10+NY10+OR10+PK10+QD10+QW10+RP10+SI10+TB10+TU10+UN10+VG10+VZ10 -> 0 | WT10: =WA10 -> 0 | WU10: =WB10 -> 0 | WW10: =WV10-WT10 -> 0 | WX10: =WV10/F10 -> 0
A11: =IFERROR(IF(WU11=0,"-","Y"),"-") -> - | C11: 28 | D11: 4 | E11: JW Gold Label Reserve 750 ml | F11: =IF(E11="","",IF(VLOOKUP(E11,'Master Data (December 2025)'!$B$10:$N$857,1)=E11,VLOOKUP(E11,'Master Data (December 2025)'!$B$10:$N$857,6),"XX")) -> 1 | H11: =IF(E11="","",IF(VLOOKUP(E11,'Master Data (December 2025)'!$B$10:$N$857,1)=E11,VLOOKUP(E11,'Master Data (December 2025)'!$B$10:$N$857,8),"XX")) -> 24 | J11: =IF(E11="","",IF(VLOOKUP(E11,'Master Data (December 2025)'!$B$10:$N$857,1)=E11,VLOOKUP(E11,'Master Data (December 2025)'!$B$10:$N$857,3),"XX")) -> สมภพ,อมฤต | K11: =IF(E11="","",IF(VLOOKUP(E11,'Master Data (December 2025)'!$B$10:$N$857,1)=E11,VLOOKUP(E11,'Master Data (December 2025)'!$B$10:$N$857,5),"XX")) -> Btl 750 ml | L11: =IF(E11="","",IF(VLOOKUP(E11,'Master Data (December 2025)'!$B$10:$N$857,1)=E11,VLOOKUP(E11,'Master Data (December 2025)'!$B$10:$N$857,11),"XX")) -> 932 | M11: =IF(E11="","",IF(VLOOKUP(E11,'Master Data (December 2025)'!$B$10:$N$857,1)=E11,VLOOKUP(E11,'Master Data (December 2025)'!$B$10:$N$857,13),"XX")) -> 38.833333 | O11: =N11 -> 0 | Z11: =(Y11*F11)/H11 -> 0 | AA11: =IF(E11=0,0,SUMIF('Cocktail (December 2025)'!$F$6:$DB$1547,E11,'Cocktail (December 2025)'!$O$6:$O$1547)) -> 0 | AB11: =AA11/H11 -> 0 | AC11: =O11+P11+Q11+R11-S11-T11-U11-V11-W11-X11-Z11-AB11 -> 0 | AD11: =AC11*H11 -> 0 | AE11: =(T11+U11+V11+W11+(X11+((Y11*$F11)/$H11)+AB11))*$L11 -> 0 | AG11: =AF11-AC11 -> 0 | AH11: =IF(AF11="",AC11,IF(AF11<>0,AF11,0)) -> 0 | AS11: =(AR11*F11)/H11 -> 0 | AT11: =IF(E11=0,0,SUMIF('Cocktail (December 2025)'!$F$6:$DB$1547,E11,'Cocktail (December 2025)'!$R$6:$R$1547)) -> 0 | AU11: =AT11/H11 -> 0 | AV11: =AH11+AI11+AJ11+AK11-AL11-AM11-AN11-AO11-AP11-AQ11-AS11-AU11 -> 0 | AW11: =AV11*H11 -> 0 | AX11: =(AM11+AN11+AO11+AP11+(AQ11+((AR11*$F11)/$H11)+AU11))*$L11 -> 0 | AZ11: =AY11-AV11 -> 0 | BA11: =AV11 -> 0 | BL11: =(BK11*F11)/H11 -> 0 | BM11: =IF(E11=0,0,SUMIF('Cocktail (December 2025)'!$F$6:$DB$1547,E11,'Cocktail (December 2025)'!$U$6:$U$1547)) -> 0 | BN11: =BM11/H11 -> 0 | BO11: =BA11+BB11+BC11+BD11-BE11-BF11-BG11-BH11-BI11-BJ11-BL11-BN11 -> 0 | BP11: =BO11*H11 -> 0 | BQ11: =(BF11+BG11+BH11+BI11+(BJ11+((BK11*$F11)/$H11)+BN11))*$L11 -> 0 | BS11: =BR11-BO11 -> 0 | BT11: =BO11 -> 0 | CE11: =(CD11*F11)/H11 -> 0 | CF11: =IF(E11=0,0,SUMIF('Cocktail (December 2025)'!$F$6:$DB$1547,E11,'Cocktail (December 2025)'!$X$6:$X$1547)) -> 0 | CG11: =CF11/H11 -> 0 | CH11: =BT11+BU11+BV11+BW11-BX11-BY11-BZ11-CA11-CB11-CC11-CE11-CG11 -> 0 | CI11: =CH11*H11 -> 0 | CJ11: =(BY11+BZ11+CA11+CB11+(CC11+((CD11*$F11)/$H11)+CG11))*$L11 -> 0 | CL11: =CK11-CH11 -> 0 | CM11: =CH11 -> 0 | CX11: =(CW11*F11)/H11 -> 0 | CY11: =IF(E11=0,0,SUMIF('Cocktail (December 2025)'!$F$6:$DB$1547,E11,'Cocktail (December 2025)'!$AA$6:$AA$1547)) -> 0 | CZ11: =CY11/H11 -> 0 | DA11: =CM11+CN11+CO11+CP11-CQ11-CR11-CS11-CT11-CU11-CV11-CX11-CZ11 -> 0 | DB11: =DA11*H11 -> 0 | DC11: =(CR11+CS11+CT11+CU11+(CV11+((CW11*$F11)/$H11)+CZ11))*$L11 -> 0 | DE11: =DD11-DA11 -> 0 | DF11: =DA11 -> 0 | DQ11: =(DP11*F11)/H11 -> 0 | DR11: =IF(E11=0,0,SUMIF('Cocktail (December 2025)'!$F$6:$DB$1547,E11,'Cocktail (December 2025)'!$AD$6:$AD$1547)) -> 0 | DS11: =DR11/H11 -> 0 | DT11: =DF11+DG11+DH11+DI11-DJ11-DK11-DL11-DM11-DN11-DO11-DQ11-DS11 -> 0 | DU11: =DT11*H11 -> 0 | DV11: =(DK11+DL11+DM11+DN11+(DO11+((DP11*$F11)/$H11)+DS11))*$L11 -> 0 | DX11: =DW11-DT11 -> 0 | DY11: =DT11 -> 0 | EJ11: =(EI11*F11)/H11 -> 0 | EK11: =IF(E11=0,0,SUMIF('Cocktail (December 2025)'!$F$6:$DB$1547,E11,'Cocktail (December 2025)'!$AG$6:$AG$1547)) -> 0 | EL11: =EK11/H11 -> 0 | EM11: =DY11+DZ11+EA11+EB11-EC11-ED11-EE11-EF11-EG11-EH11-EJ11-EL11 -> 0 | EN11: =EM11*H11 -> 0 | EO11: =(ED11+EE11+EF11+EG11+(EH11+((EI11*$F11)/$H11)+EL11))*$L11 -> 0 | EQ11: =EP11-EM11 -> 0 | ER11: =EM11 -> 0 | FC11: =(FB11*F11)/H11 -> 0 | FD11: =IF(E11=0,0,SUMIF('Cocktail (December 2025)'!$F$6:$DB$1547,E11,'Cocktail (December 2025)'!$AJ$6:$AJ$1547)) -> 0 | FE11: =FD11/H11 -> 0 | FF11: =ER11+ES11+ET11+EU11-EV11-EW11-EX11-EY11-EZ11-FA11-FC11-FE11 -> 0 | FG11: =FF11*H11 -> 0 | FH11: =(EW11+EX11+EY11+EZ11+(FA11+((FB11*$F11)/$H11)+FE11))*$L11 -> 0 | FJ11: =FI11-FF11 -> 0 | FK11: =FF11 -> 0 | FV11: =(FU11*F11)/H11 -> 0 | FW11: =IF(E11=0,0,SUMIF('Cocktail (December 2025)'!$F$6:$DB$1547,E11,'Cocktail (December 2025)'!$AM$6:$AM$1547)) -> 0 | FX11: =FW11/H11 -> 0 | FY11: =FK11+FL11+FM11+FN11-FO11-FP11-FQ11-FR11-FS11-FT11-FV11-FX11 -> 0 | FZ11: =FY11*H11 -> 0 | GA11: =(FP11+FQ11+FR11+FS11+(FT11+((FU11*$F11)/$H11)+FX11))*$L11 -> 0 | GC11: =GB11-FY11 -> 0 | GD11: =FY11 -> 0 | GO11: =(GN11*F11)/H11 -> 0 | GP11: =IF(E11=0,0,SUMIF('Cocktail (December 2025)'!$F$6:$DB$1547,E11,'Cocktail (December 2025)'!$AP$6:$AP$1547)) -> 0 | GQ11: =GP11/H11 -> 0 | GR11: =GD11+GE11+GF11+GG11-GH11-GI11-GJ11-GK11-GL11-GM11-GO11-GQ11 -> 0 | GS11: =GR11*H11 -> 0 | GT11: =(GI11+GJ11+GK11+GL11+(GM11+((GN11*$F11)/$H11)+GQ11))*$L11 -> 0 | GV11: =GU11-GR11 -> 0 | GW11: =GR11 -> 0 | HH11: =(HG11*F11)/H11 -> 0 | HI11: =IF(E11=0,0,SUMIF('Cocktail (December 2025)'!$F$6:$DB$1547,E11,'Cocktail (December 2025)'!$AS$6:$AS$1547)) -> 0 | HJ11: =HI11/H11 -> 0 | HK11: =GW11+GX11+GY11+GZ11-HA11-HB11-HC11-HD11-HE11-HF11-HH11-HJ11 -> 0 | HL11: =HK11*H11 -> 0 | HM11: =(HB11+HC11+HD11+HE11+(HF11+((HG11*$F11)/$H11)+HJ11))*$L11 -> 0 | HO11: =HN11-HK11 -> 0 | HP11: =HK11 -> 0 | IA11: =(HZ11*F11)/H11 -> 0 | IB11: =IF(E11=0,0,SUMIF('Cocktail (December 2025)'!$F$6:$DB$1547,E11,'Cocktail (December 2025)'!$AV$6:$AV$1547)) -> 0 | IC11: =IB11/H11 -> 0 | ID11: =HP11+HQ11+HR11+HS11-HT11-HU11-HV11-HW11-HX11-HY11-IA11-IC11 -> 0 | IE11: =ID11*H11 -> 0 | IF11: =(HU11+HV11+HW11+HX11+(HY11+((HZ11*$F11)/$H11)+IC11))*$L11 -> 0 | IH11: =IG11-ID11 -> 0 | II11: =ID11 -> 0 | IT11: =(IS11*F11)/H11 -> 0 | IU11: =IF(E11=0,0,SUMIF('Cocktail (December 2025)'!$F$6:$DB$1547,E11,'Cocktail (December 2025)'!$AY$6:$AY$1547)) -> 0 | IV11: =IU11/H11 -> 0 | IW11: =II11+IJ11+IK11+IL11-IM11-IN11-IO11-IP11-IQ11-IR11-IT11-IV11 -> 0 | IX11: =IW11*H11 -> 0 | IY11: =(IN11+IO11+IP11+IQ11+(IR11+((IS11*$F11)/$H11)+IV11))*$L11 -> 0 | JA11: =IZ11-IW11 -> 0 | JB11: =IW11 -> 0 | JM11: =(JL11*F11)/H11 -> 0 | JN11: =IF(E11=0,0,SUMIF('Cocktail (December 2025)'!$F$6:$DB$1547,E11,'Cocktail (December 2025)'!$BB$6:$BB$1547)) -> 0 | JO11: =JN11/H11 -> 0 | JP11: =JB11+JC11+JD11+JE11-JF11-JG11-JH11-JI11-JJ11-JK11-JM11-JO11 -> 0 | JQ11: =JP11*H11 -> 0 | JR11: =(JG11+JH11+JI11+JJ11+(JK11+((JL11*$F11)/$H11)+JO11))*$L11 -> 0 | JT11: =JS11-JP11 -> 0 | JU11: =JP11 -> 0 | KF11: =(KE11*F11)/H11 -> 0 | KG11: =IF(E11=0,0,SUMIF('Cocktail (December 2025)'!$F$6:$DB$1547,E11,'Cocktail (December 2025)'!$BE$6:$BE$1547)) -> 0 | KH11: =KG11/H11 -> 0 | KI11: =JU11+JV11+JW11+JX11-JY11-JZ11-KA11-KB11-KC11-KD11-KF11-KH11 -> 0 | KJ11: =KI11*H11 -> 0 | KK11: =(JZ11+KA11+KB11+KC11+(KD11+((KE11*$F11)/$H11)+KH11))*$L11 -> 0 | KM11: =KL11-KI11 -> 0 | KN11: =KI11 -> 0 | KY11: =(KX11*F11)/H11 -> 0 | KZ11: =IF(E11=0,0,SUMIF('Cocktail (December 2025)'!$F$6:$DB$1547,E11,'Cocktail (December 2025)'!$BH$6:$BH$1547)) -> 0 | LA11: =KZ11/H11 -> 0 | LB11: =KN11+KO11+KP11+KQ11-KR11-KS11-KT11-KU11-KV11-KW11-KY11-LA11 -> 0 | LC11: =LB11*H11 -> 0 | LD11: =(KS11+KT11+KU11+KV11+(KW11+((KX11*$F11)/$H11)+LA11))*$L11 -> 0 | LF11: =LE11-LB11 -> 0 | LG11: =LB11 -> 0 | LR11: =(LQ11*F11)/H11 -> 0 | LS11: =IF(E11=0,0,SUMIF('Cocktail (December 2025)'!$F$6:$DB$1547,E11,'Cocktail (December 2025)'!$BK$6:$BK$1547)) -> 0 | LT11: =LS11/H11 -> 0 | LU11: =LG11+LH11+LI11+LJ11-LK11-LL11-LM11-LN11-LO11-LP11-LR11-LT11 -> 0 | LV11: =LU11*H11 -> 0 | LW11: =(LL11+LM11+LN11+LO11+(LP11+((LQ11*$F11)/$H11)+LT11))*$L11 -> 0 | LY11: =LX11-LU11 -> 0 | LZ11: =LU11 -> 0 | MK11: =(MJ11*F11)/H11 -> 0 | ML11: =IF(E11=0,0,SUMIF('Cocktail (December 2025)'!$F$6:$DB$1547,E11,'Cocktail (December 2025)'!$BN$6:$BN$1547)) -> 0 | MM11: =ML11/H11 -> 0 | MN11: =LZ11+MA11+MB11+MC11-MD11-ME11-MF11-MG11-MH11-MI11-MK11-MM11 -> 0 | MO11: =MN11*H11 -> 0 | MP11: =(ME11+MF11+MG11+MH11+(MI11+((MJ11*$F11)/$H11)+MM11))*$L11 -> 0 | MR11: =MQ11-MN11 -> 0 | MS11: =MN11 -> 0 | ND11: =(NC11*F11)/H11 -> 0 | NE11: =IF(E11=0,0,SUMIF('Cocktail (December 2025)'!$F$6:$DB$1547,E11,'Cocktail (December 2025)'!$BQ$6:$BQ$1547)) -> 0 | NF11: =NE11/H11 -> 0 | NG11: =MS11+MT11+MU11+MV11-MW11-MX11-MY11-MZ11-NA11-NB11-ND11-NF11 -> 0 | NH11: =NG11*H11 -> 0 | NI11: =(MX11+MY11+MZ11+NA11+(NB11+((NC11*$F11)/$H11)+NF11))*$L11 -> 0 | NK11: =NJ11-NG11 -> 0 | NL11: =NG11 -> 0 | NW11: =(NV11*F11)/H11 -> 0 | NX11: =IF(E11=0,0,SUMIF('Cocktail (December 2025)'!$F$6:$DB$1547,E11,'Cocktail (December 2025)'!$BT$6:$BT$1547)) -> 0 | NY11: =NX11/H11 -> 0 | NZ11: =NL11+NM11+NN11+NO11-NP11-NQ11-NR11-NS11-NT11-NU11-NW11-NY11 -> 0 | OA11: =NZ11*H11 -> 0 | OB11: =(NQ11+NR11+NS11+NT11+(NU11+((NV11*$F11)/$H11)+NY11))*$L11 -> 0 | OD11: =OC11-NZ11 -> 0 | OE11: =NZ11 -> 0 | OP11: =(OO11*F11)/H11 -> 0 | OQ11: =IF(E11=0,0,SUMIF('Cocktail (December 2025)'!$F$6:$DB$1547,E11,'Cocktail (December 2025)'!$BW$6:$BW$1547)) -> 0 | OR11: =OQ11/H11 -> 0 | OS11: =OE11+OF11+OG11+OH11-OI11-OJ11-OK11-OL11-OM11-ON11-OP11-OR11 -> 0 | OT11: =OS11*H11 -> 0 | OU11: =(OJ11+OK11+OL11+OM11+(ON11+((OO11*$F11)/$H11)+OR11))*$L11 -> 0 | OW11: =OV11-OS11 -> 0 | OX11: =OS11 -> 0 | PI11: =(PH11*F11)/H11 -> 0 | PJ11: =IF(E11=0,0,SUMIF('Cocktail (December 2025)'!$F$6:$DB$1547,E11,'Cocktail (December 2025)'!$BZ$6:$BZ$1547)) -> 0 | PK11: =PJ11/H11 -> 0 | PL11: =OX11+OY11+OZ11+PA11-PB11-PC11-PD11-PE11-PF11-PG11-PI11-PK11 -> 0 | PM11: =PL11*H11 -> 0 | PN11: =(PC11+PD11+PE11+PF11+(PG11+((PH11*$F11)/$H11)+PK11))*$L11 -> 0 | PP11: =PO11-PL11 -> 0 | PQ11: =PL11 -> 0 | QB11: =(QA11*F11)/H11 -> 0 | QC11: =IF(E11=0,0,SUMIF('Cocktail (December 2025)'!$F$6:$DB$1547,E11,'Cocktail (December 2025)'!$CC$6:$CC$1547)) -> 0 | QD11: =QC11/H11 -> 0 | QE11: =PQ11+PR11+PS11+PT11-PU11-PV11-PW11-PX11-PY11-PZ11-QB11-QD11 -> 0 | QF11: =QE11*H11 -> 0 | QG11: =(PV11+PW11+PX11+PY11+(PZ11+((QA11*$F11)/$H11)+QD11))*$L11 -> 0 | QI11: =QH11-QE11 -> 0 | QJ11: =QE11 -> 0 | QU11: =(QT11*F11)/H11 -> 0 | QV11: =IF(E11=0,0,SUMIF('Cocktail (December 2025)'!$F$6:$DB$1547,E11,'Cocktail (December 2025)'!$CF$6:$CF$1547)) -> 0 | QW11: =QV11/H11 -> 0 | QX11: =QJ11+QK11+QL11+QM11-QN11-QO11-QP11-QQ11-QR11-QS11-QU11-QW11 -> 0 | QY11: =QX11*H11 -> 0 | QZ11: =(QO11+QP11+QQ11+QR11+(QS11+((QT11*$F11)/$H11)+QW11))*$L11 -> 0 | RB11: =RA11-QX11 -> 0 | RC11: =QX11 -> 0 | RN11: =(RM11*F11)/H11 -> 0 | RO11: =IF(E11=0,0,SUMIF('Cocktail (December 2025)'!$F$6:$DB$1547,E11,'Cocktail (December 2025)'!$CI$6:$CI$1547)) -> 0 | RP11: =RO11/H11 -> 0 | RQ11: =RC11+RD11+RE11+RF11-RG11-RH11-RI11-RJ11-RK11-RL11-RN11-RP11 -> 0 | RR11: =RQ11*H11 -> 0 | RS11: =(RH11+RI11+RJ11+RK11+(RL11+((RM11*$F11)/$H11)+RP11))*$L11 -> 0 | RU11: =RT11-RQ11 -> 0 | RV11: =RQ11 -> 0 | SG11: =(SF11*F11)/H11 -> 0 | SH11: =IF(E11=0,0,SUMIF('Cocktail (December 2025)'!$F$6:$DB$1547,E11,'Cocktail (December 2025)'!$CL$6:$CL$1547)) -> 0 | SI11: =SH11/H11 -> 0 | SJ11: =RV11+RW11+RX11+RY11-RZ11-SA11-SB11-SC11-SD11-SE11-SG11-SI11 -> 0 | SK11: =SJ11*H11 -> 0 | SL11: =(SA11+SB11+SC11+SD11+(SE11+((SF11*$F11)/$H11)+SI11))*$L11 -> 0 | SN11: =SM11-SJ11 -> 0 | SO11: =SJ11 -> 0 | SZ11: =(SY11*F11)/H11 -> 0 | TA11: =IF(E11=0,0,SUMIF('Cocktail (December 2025)'!$F$6:$DB$1547,E11,'Cocktail (December 2025)'!$CO$6:$CO$1547)) -> 0 | TB11: =TA11/H11 -> 0 | TC11: =SO11+SP11+SQ11+SR11-SS11-ST11-SU11-SV11-SW11-SX11-SZ11-TB11 -> 0 | TD11: =TC11*H11 -> 0 | TE11: =(ST11+SU11+SV11+SW11+(SX11+((SY11*$F11)/$H11)+TB11))*$L11 -> 0 | TG11: =TF11-TC11 -> 0 | TH11: =TC11 -> 0 | TS11: =(TR11*F11)/H11 -> 0 | TT11: =IF(E11=0,0,SUMIF('Cocktail (December 2025)'!$F$6:$DB$1547,E11,'Cocktail (December 2025)'!$CR$6:$CR$1547)) -> 0 | TU11: =TT11/H11 -> 0 | TV11: =TH11+TI11+TJ11+TK11-TL11-TM11-TN11-TO11-TP11-TQ11-TS11-TU11 -> 0 | TW11: =TV11*H11 -> 0 | TX11: =(TM11+TN11+TO11+TP11+(TQ11+((TR11*$F11)/$H11)+TU11))*$L11 -> 0 | TZ11: =TY11-TV11 -> 0 | UA11: =TV11 -> 0 | UL11: =(UK11*F11)/H11 -> 0 | UM11: =IF(E11=0,0,SUMIF('Cocktail (December 2025)'!$F$6:$DB$1547,E11,'Cocktail (December 2025)'!$CU$6:$CU$1547)) -> 0 | UN11: =UM11/H11 -> 0 | UO11: =UA11+UB11+UC11+UD11-UE11-UF11-UG11-UH11-UI11-UJ11-UL11-UN11 -> 0 | UP11: =UO11*H11 -> 0 | UQ11: =(UF11+UG11+UH11+UI11+(UJ11+((UK11*$F11)/$H11)+UN11))*$L11 -> 0 | US11: =UR11-UO11 -> 0 | UT11: =UO11 -> 0 | VE11: =(VD11*F11)/H11 -> 0 | VF11: =IF(E11=0,0,SUMIF('Cocktail (December 2025)'!$F$6:$DB$1547,E11,'Cocktail (December 2025)'!$CX$6:$CX$1547)) -> 0 | VG11: =VF11/H11 -> 0 | VH11: =UT11+UU11+UV11+UW11-UX11-UY11-UZ11-VA11-VB11-VC11-VE11-VG11 -> 0 | VI11: =VH11*H11 -> 0 | VJ11: =(UY11+UZ11+VA11+VB11+(VC11+((VD11*$F11)/$H11)+VG11))*$L11 -> 0 | VL11: =VK11-VH11 -> 0 | VM11: =VH11 -> 0 | VX11: =(VW11*F11)/H11 -> 0 | VY11: =IF(E11=0,0,SUMIF('Cocktail (December 2025)'!$F$6:$DB$1547,E11,'Cocktail (December 2025)'!$DA$6:$DA$1547)) -> 0 | VZ11: =VY11/H11 -> 0 | WA11: =VM11+VN11+VO11+VP11-VQ11-VR11-VS11-VT11-VU11-VV11-VX11-VZ11 -> 0 | WB11: =WA11*H11 -> 0 | WC11: =(VR11+VS11+VT11+VU11+(VV11+((VW11*$F11)/$H11)+VZ11))*$L11 -> 0 | WE11: =WD11-WA11 -> 0 | WF11: X | WG11: =O11 -> 0 | WH11: =P11+AI11+BB11+BU11+CN11+DG11+DZ11+ES11+FL11+GE11+GX11+HQ11+IJ11+JC11+JV11+KO11+LH11+MA11+MT11+NM11+OF11+OY11+PR11+QK11+RD11+RW11+SP11+TI11+UB11+UU11+VN11 -> 0 | WI11: =Q11+AJ11+BC11+BV11+CO11+DH11+EA11+ET11+FM11+GF11+GY11+HR11+IK11+JD11+JW11+KP11+LI11+MB11+MU11+NN11+OG11+OZ11+PS11+QL11+RE11+RX11+SQ11+TJ11+UC11+UV11+VO11 -> 0 | WJ11: =R11+AK11+BD11+BW11+CP11+DI11+EB11+EU11+FN11+GG11+GZ11+HS11+IL11+JE11+JX11+KQ11+LJ11+MC11+MV11+NO11+OH11+PA11+PT11+QM11+RF11+RY11+SR11+TK11+UD11+UW11+VP11 -> 0 | WK11: =S11+AL11+BE11+BX11+CQ11+DJ11+EC11+EV11+FO11+GH11+HA11+HT11+IM11+JF11+JY11+KR11+LK11+MD11+MW11+NP11+OI11+PB11+PU11+QN11+RG11+RZ11+SS11+TL11+UE11+UX11+VQ11 -> 0 | WL11: =T11+AM11+BF11+BY11+CR11+DK11+ED11+EW11+FP11+GI11+HB11+HU11+IN11+JG11+JZ11+KS11+LL11+ME11+MX11+NQ11+OJ11+PC11+PV11+QO11+RH11+SA11+ST11+TM11+UF11+UY11+VR11 -> 0 | WM11: =U11+AN11+BG11+BZ11+CS11+DL11+EE11++EX11+FQ11+GJ11+HC11+HV11+IO11+JH11+KA11+KT11+LM11+MF11+MY11+NR11+OK11+PD11+PW11+QP11+RI11+SB11+SU11+TN11+UG11+UZ11+VS11 -> 0 | WN11: =V11+AO11+BH11+CA11+CT11+DM11+EF11+EY11+FR11+GK11+HD11+HW11+IP11+JI11+KB11+KU11+LN11+MG11+MZ11+NS11+OL11+PE11+PX11+QQ11+RJ11+SC11+SV11+TO11+UH11+VA11+VT11 -> 0 | WO11: =W11+AP11+BI11+CB11+CU11+DN11+EG11+EZ11+FS11+GL11+HE11+HX11+IQ11+JJ11+KC11+KV11+LO11+MH11+NA11+NT11+OM11+PF11+PY11+QR11+RK11+SD11+SW11+TP11+UI11+VB11+VU11 -> 0 | WP11: =X11+AQ11+BJ11+CC11+CV11+DO11+EH11+FA11+FT11+GM11+HF11+HY11+IR11+JK11+KD11+KW11+LP11+MI11+NB11+NU11+ON11+PG11+PZ11+QS11+RL11+SE11+SX11+TQ11+UJ11+VC11+VV11 -> 0 | WQ11: =Y11+AR11+BK11+CD11+CW11+DP11+EI11+FB11+FU11+GN11+HG11+HZ11+IS11+JL11+KE11+KX11+LQ11+MJ11+NC11+NV11+OO11+PH11+QA11+QT11+RM11+SF11+SY11+TR11+UK11+VD11+VW11 -> 0 | WR11: =Z11+AS11+BL11+CE11+CX11+DQ11+EJ11+FC11+FV11+GO11+HH11+IA11+IT11+JM11+KF11+KY11+LR11+MK11+ND11+NW11+OP11+PI11+QB11+QU11+RN11+SG11+SZ11+TS11+UL11+VE11+VX11 -> 0 | WS11: =AB11+AU11+BN11+CG11+CZ11+DS11+EL11+FE11+FX11+GQ11+HJ11+IC11+IV11+JO11+KH11+LA11+LT11+MM11+NF11+NY11+OR11+PK11+QD11+QW11+RP11+SI11+TB11+TU11+UN11+VG11+VZ11 -> 0 | WT11: =WA11 -> 0 | WU11: =WB11 -> 0 | WW11: =WV11-WT11 -> 0 | WX11: =WV11/F11 -> 0
A12: =IFERROR(IF(WU12=0,"-","Y"),"-") -> - | C12: 27 | D12: 3 | E12: JW Johnnie Blonde 750 ml | F12: =IF(E12="","",IF(VLOOKUP(E12,'Master Data (December 2025)'!$B$10:$N$857,1)=E12,VLOOKUP(E12,'Master Data (December 2025)'!$B$10:$N$857,6),"XX")) -> 1 | H12: =IF(E12="","",IF(VLOOKUP(E12,'Master Data (December 2025)'!$B$10:$N$857,1)=E12,VLOOKUP(E12,'Master Data (December 2025)'!$B$10:$N$857,8),"XX")) -> 24 | J12: =IF(E12="","",IF(VLOOKUP(E12,'Master Data (December 2025)'!$B$10:$N$857,1)=E12,VLOOKUP(E12,'Master Data (December 2025)'!$B$10:$N$857,3),"XX")) -> สมภพ,อมฤต | K12: =IF(E12="","",IF(VLOOKUP(E12,'Master Data (December 2025)'!$B$10:$N$857,1)=E12,VLOOKUP(E12,'Master Data (December 2025)'!$B$10:$N$857,5),"XX")) -> Btl 750 ml | L12: =IF(E12="","",IF(VLOOKUP(E12,'Master Data (December 2025)'!$B$10:$N$857,1)=E12,VLOOKUP(E12,'Master Data (December 2025)'!$B$10:$N$857,11),"XX")) -> 2168 | M12: =IF(E12="","",IF(VLOOKUP(E12,'Master Data (December 2025)'!$B$10:$N$857,1)=E12,VLOOKUP(E12,'Master Data (December 2025)'!$B$10:$N$857,13),"XX")) -> 90.333333 | O12: =N12 -> 0 | Z12: =(Y12*F12)/H12 -> 0 | AA12: =IF(E12=0,0,SUMIF('Cocktail (December 2025)'!$F$6:$DB$1547,E12,'Cocktail (December 2025)'!$O$6:$O$1547)) -> 0 | AB12: =AA12/H12 -> 0 | AC12: =O12+P12+Q12+R12-S12-T12-U12-V12-W12-X12-Z12-AB12 -> 0 | AD12: =AC12*H12 -> 0 | AE12: =(T12+U12+V12+W12+(X12+((Y12*$F12)/$H12)+AB12))*$L12 -> 0 | AG12: =AF12-AC12 -> 0 | AH12: =IF(AF12="",AC12,IF(AF12<>0,AF12,0)) -> 0 | AS12: =(AR12*F12)/H12 -> 0 | AT12: =IF(E12=0,0,SUMIF('Cocktail (December 2025)'!$F$6:$DB$1547,E12,'Cocktail (December 2025)'!$R$6:$R$1547)) -> 0 | AU12: =AT12/H12 -> 0 | AV12: =AH12+AI12+AJ12+AK12-AL12-AM12-AN12-AO12-AP12-AQ12-AS12-AU12 -> 0 | AW12: =AV12*H12 -> 0 | AX12: =(AM12+AN12+AO12+AP12+(AQ12+((AR12*$F12)/$H12)+AU12))*$L12 -> 0 | AZ12: =AY12-AV12 -> 0 | BA12: =AV12 -> 0 | BL12: =(BK12*F12)/H12 -> 0 | BM12: =IF(E12=0,0,SUMIF('Cocktail (December 2025)'!$F$6:$DB$1547,E12,'Cocktail (December 2025)'!$U$6:$U$1547)) -> 0 | BN12: =BM12/H12 -> 0 | BO12: =BA12+BB12+BC12+BD12-BE12-BF12-BG12-BH12-BI12-BJ12-BL12-BN12 -> 0 | BP12: =BO12*H12 -> 0 | BQ12: =(BF12+BG12+BH12+BI12+(BJ12+((BK12*$F12)/$H12)+BN12))*$L12 -> 0 | BS12: =BR12-BO12 -> 0 | BT12: =BO12 -> 0 | CE12: =(CD12*F12)/H12 -> 0 | CF12: =IF(E12=0,0,SUMIF('Cocktail (December 2025)'!$F$6:$DB$1547,E12,'Cocktail (December 2025)'!$X$6:$X$1547)) -> 0 | CG12: =CF12/H12 -> 0 | CH12: =BT12+BU12+BV12+BW12-BX12-BY12-BZ12-CA12-CB12-CC12-CE12-CG12 -> 0 | CI12: =CH12*H12 -> 0 | CJ12: =(BY12+BZ12+CA12+CB12+(CC12+((CD12*$F12)/$H12)+CG12))*$L12 -> 0 | CL12: =CK12-CH12 -> 0 | CM12: =CH12 -> 0 | CX12: =(CW12*F12)/H12 -> 0 | CY12: =IF(E12=0,0,SUMIF('Cocktail (December 2025)'!$F$6:$DB$1547,E12,'Cocktail (December 2025)'!$AA$6:$AA$1547)) -> 0 | CZ12: =CY12/H12 -> 0 | DA12: =CM12+CN12+CO12+CP12-CQ12-CR12-CS12-CT12-CU12-CV12-CX12-CZ12 -> 0 | DB12: =DA12*H12 -> 0 | DC12: =(CR12+CS12+CT12+CU12+(CV12+((CW12*$F12)/$H12)+CZ12))*$L12 -> 0 | DE12: =DD12-DA12 -> 0 | DF12: =DA12 -> 0 | DQ12: =(DP12*F12)/H12 -> 0 | DR12: =IF(E12=0,0,SUMIF('Cocktail (December 2025)'!$F$6:$DB$1547,E12,'Cocktail (December 2025)'!$AD$6:$AD$1547)) -> 0 | DS12: =DR12/H12 -> 0 | DT12: =DF12+DG12+DH12+DI12-DJ12-DK12-DL12-DM12-DN12-DO12-DQ12-DS12 -> 0 | DU12: =DT12*H12 -> 0 | DV12: =(DK12+DL12+DM12+DN12+(DO12+((DP12*$F12)/$H12)+DS12))*$L12 -> 0 | DX12: =DW12-DT12 -> 0 | DY12: =DT12 -> 0 | EJ12: =(EI12*F12)/H12 -> 0 | EK12: =IF(E12=0,0,SUMIF('Cocktail (December 2025)'!$F$6:$DB$1547,E12,'Cocktail (December 2025)'!$AG$6:$AG$1547)) -> 0 | EL12: =EK12/H12 -> 0 | EM12: =DY12+DZ12+EA12+EB12-EC12-ED12-EE12-EF12-EG12-EH12-EJ12-EL12 -> 0 | EN12: =EM12*H12 -> 0 | EO12: =(ED12+EE12+EF12+EG12+(EH12+((EI12*$F12)/$H12)+EL12))*$L12 -> 0 | EQ12: =EP12-EM12 -> 0 | ER12: =EM12 -> 0 | FC12: =(FB12*F12)/H12 -> 0 | FD12: =IF(E12=0,0,SUMIF('Cocktail (December 2025)'!$F$6:$DB$1547,E12,'Cocktail (December 2025)'!$AJ$6:$AJ$1547)) -> 0 | FE12: =FD12/H12 -> 0 | FF12: =ER12+ES12+ET12+EU12-EV12-EW12-EX12-EY12-EZ12-FA12-FC12-FE12 -> 0 | FG12: =FF12*H12 -> 0 | FH12: =(EW12+EX12+EY12+EZ12+(FA12+((FB12*$F12)/$H12)+FE12))*$L12 -> 0 | FJ12: =FI12-FF12 -> 0 | FK12: =FF12 -> 0 | FV12: =(FU12*F12)/H12 -> 0 | FW12: =IF(E12=0,0,SUMIF('Cocktail (December 2025)'!$F$6:$DB$1547,E12,'Cocktail (December 2025)'!$AM$6:$AM$1547)) -> 0 | FX12: =FW12/H12 -> 0 | FY12: =FK12+FL12+FM12+FN12-FO12-FP12-FQ12-FR12-FS12-FT12-FV12-FX12 -> 0 | FZ12: =FY12*H12 -> 0 | GA12: =(FP12+FQ12+FR12+FS12+(FT12+((FU12*$F12)/$H12)+FX12))*$L12 -> 0 | GC12: =GB12-FY12 -> 0 | GD12: =FY12 -> 0 | GO12: =(GN12*F12)/H12 -> 0 | GP12: =IF(E12=0,0,SUMIF('Cocktail (December 2025)'!$F$6:$DB$1547,E12,'Cocktail (December 2025)'!$AP$6:$AP$1547)) -> 0 | GQ12: =GP12/H12 -> 0 | GR12: =GD12+GE12+GF12+GG12-GH12-GI12-GJ12-GK12-GL12-GM12-GO12-GQ12 -> 0 | GS12: =GR12*H12 -> 0 | GT12: =(GI12+GJ12+GK12+GL12+(GM12+((GN12*$F12)/$H12)+GQ12))*$L12 -> 0 | GV12: =GU12-GR12 -> 0 | GW12: =GR12 -> 0 | HH12: =(HG12*F12)/H12 -> 0 | HI12: =IF(E12=0,0,SUMIF('Cocktail (December 2025)'!$F$6:$DB$1547,E12,'Cocktail (December 2025)'!$AS$6:$AS$1547)) -> 0 | HJ12: =HI12/H12 -> 0 | HK12: =GW12+GX12+GY12+GZ12-HA12-HB12-HC12-HD12-HE12-HF12-HH12-HJ12 -> 0 | HL12: =HK12*H12 -> 0 | HM12: =(HB12+HC12+HD12+HE12+(HF12+((HG12*$F12)/$H12)+HJ12))*$L12 -> 0 | HO12: =HN12-HK12 -> 0 | HP12: =HK12 -> 0 | IA12: =(HZ12*F12)/H12 -> 0 | IB12: =IF(E12=0,0,SUMIF('Cocktail (December 2025)'!$F$6:$DB$1547,E12,'Cocktail (December 2025)'!$AV$6:$AV$1547)) -> 0 | IC12: =IB12/H12 -> 0 | ID12: =HP12+HQ12+HR12+HS12-HT12-HU12-HV12-HW12-HX12-HY12-IA12-IC12 -> 0 | IE12: =ID12*H12 -> 0 | IF12: =(HU12+HV12+HW12+HX12+(HY12+((HZ12*$F12)/$H12)+IC12))*$L12 -> 0 | IH12: =IG12-ID12 -> 0 | II12: =ID12 -> 0 | IT12: =(IS12*F12)/H12 -> 0 | IU12: =IF(E12=0,0,SUMIF('Cocktail (December 2025)'!$F$6:$DB$1547,E12,'Cocktail (December 2025)'!$AY$6:$AY$1547)) -> 0 | IV12: =IU12/H12 -> 0 | IW12: =II12+IJ12+IK12+IL12-IM12-IN12-IO12-IP12-IQ12-IR12-IT12-IV12 -> 0 | IX12: =IW12*H12 -> 0 | IY12: =(IN12+IO12+IP12+IQ12+(IR12+((IS12*$F12)/$H12)+IV12))*$L12 -> 0 | JA12: =IZ12-IW12 -> 0 | JB12: =IW12 -> 0 | JM12: =(JL12*F12)/H12 -> 0 | JN12: =IF(E12=0,0,SUMIF('Cocktail (December 2025)'!$F$6:$DB$1547,E12,'Cocktail (December 2025)'!$BB$6:$BB$1547)) -> 0 | JO12: =JN12/H12 -> 0 | JP12: =JB12+JC12+JD12+JE12-JF12-JG12-JH12-JI12-JJ12-JK12-JM12-JO12 -> 0 | JQ12: =JP12*H12 -> 0 | JR12: =(JG12+JH12+JI12+JJ12+(JK12+((JL12*$F12)/$H12)+JO12))*$L12 -> 0 | JT12: =JS12-JP12 -> 0 | JU12: =JP12 -> 0 | KF12: =(KE12*F12)/H12 -> 0 | KG12: =IF(E12=0,0,SUMIF('Cocktail (December 2025)'!$F$6:$DB$1547,E12,'Cocktail (December 2025)'!$BE$6:$BE$1547)) -> 0 | KH12: =KG12/H12 -> 0 | KI12: =JU12+JV12+JW12+JX12-JY12-JZ12-KA12-KB12-KC12-KD12-KF12-KH12 -> 0 | KJ12: =KI12*H12 -> 0 | KK12: =(JZ12+KA12+KB12+KC12+(KD12+((KE12*$F12)/$H12)+KH12))*$L12 -> 0 | KM12: =KL12-KI12 -> 0 | KN12: =KI12 -> 0 | KY12: =(KX12*F12)/H12 -> 0 | KZ12: =IF(E12=0,0,SUMIF('Cocktail (December 2025)'!$F$6:$DB$1547,E12,'Cocktail (December 2025)'!$BH$6:$BH$1547)) -> 0 | LA12: =KZ12/H12 -> 0 | LB12: =KN12+KO12+KP12+KQ12-KR12-KS12-KT12-KU12-KV12-KW12-KY12-LA12 -> 0 | LC12: =LB12*H12 -> 0 | LD12: =(KS12+KT12+KU12+KV12+(KW12+((KX12*$F12)/$H12)+LA12))*$L12 -> 0 | LF12: =LE12-LB12 -> 0 | LG12: =LB12 -> 0 | LR12: =(LQ12*F12)/H12 -> 0 | LS12: =IF(E12=0,0,SUMIF('Cocktail (December 2025)'!$F$6:$DB$1547,E12,'Cocktail (December 2025)'!$BK$6:$BK$1547)) -> 0 | LT12: =LS12/H12 -> 0 | LU12: =LG12+LH12+LI12+LJ12-LK12-LL12-LM12-LN12-LO12-LP12-LR12-LT12 -> 0 | LV12: =LU12*H12 -> 0 | LW12: =(LL12+LM12+LN12+LO12+(LP12+((LQ12*$F12)/$H12)+LT12))*$L12 -> 0 | LY12: =LX12-LU12 -> 0 | LZ12: =LU12 -> 0 | MK12: =(MJ12*F12)/H12 -> 0 | ML12: =IF(E12=0,0,SUMIF('Cocktail (December 2025)'!$F$6:$DB$1547,E12,'Cocktail (December 2025)'!$BN$6:$BN$1547)) -> 0 | MM12: =ML12/H12 -> 0 | MN12: =LZ12+MA12+MB12+MC12-MD12-ME12-MF12-MG12-MH12-MI12-MK12-MM12 -> 0 | MO12: =MN12*H12 -> 0 | MP12: =(ME12+MF12+MG12+MH12+(MI12+((MJ12*$F12)/$H12)+MM12))*$L12 -> 0 | MR12: =MQ12-MN12 -> 0 | MS12: =MN12 -> 0 | ND12: =(NC12*F12)/H12 -> 0 | NE12: =IF(E12=0,0,SUMIF('Cocktail (December 2025)'!$F$6:$DB$1547,E12,'Cocktail (December 2025)'!$BQ$6:$BQ$1547)) -> 0 | NF12: =NE12/H12 -> 0 | NG12: =MS12+MT12+MU12+MV12-MW12-MX12-MY12-MZ12-NA12-NB12-ND12-NF12 -> 0 | NH12: =NG12*H12 -> 0 | NI12: =(MX12+MY12+MZ12+NA12+(NB12+((NC12*$F12)/$H12)+NF12))*$L12 -> 0 | NK12: =NJ12-NG12 -> 0 | NL12: =NG12 -> 0 | NW12: =(NV12*F12)/H12 -> 0 | NX12: =IF(E12=0,0,SUMIF('Cocktail (December 2025)'!$F$6:$DB$1547,E12,'Cocktail (December 2025)'!$BT$6:$BT$1547)) -> 0 | NY12: =NX12/H12 -> 0 | NZ12: =NL12+NM12+NN12+NO12-NP12-NQ12-NR12-NS12-NT12-NU12-NW12-NY12 -> 0 | OA12: =NZ12*H12 -> 0 | OB12: =(NQ12+NR12+NS12+NT12+(NU12+((NV12*$F12)/$H12)+NY12))*$L12 -> 0 | OD12: =OC12-NZ12 -> 0 | OE12: =NZ12 -> 0 | OP12: =(OO12*F12)/H12 -> 0 | OQ12: =IF(E12=0,0,SUMIF('Cocktail (December 2025)'!$F$6:$DB$1547,E12,'Cocktail (December 2025)'!$BW$6:$BW$1547)) -> 0 | OR12: =OQ12/H12 -> 0 | OS12: =OE12+OF12+OG12+OH12-OI12-OJ12-OK12-OL12-OM12-ON12-OP12-OR12 -> 0 | OT12: =OS12*H12 -> 0 | OU12: =(OJ12+OK12+OL12+OM12+(ON12+((OO12*$F12)/$H12)+OR12))*$L12 -> 0 | OW12: =OV12-OS12 -> 0 | OX12: =OS12 -> 0 | PI12: =(PH12*F12)/H12 -> 0 | PJ12: =IF(E12=0,0,SUMIF('Cocktail (December 2025)'!$F$6:$DB$1547,E12,'Cocktail (December 2025)'!$BZ$6:$BZ$1547)) -> 0 | PK12: =PJ12/H12 -> 0 | PL12: =OX12+OY12+OZ12+PA12-PB12-PC12-PD12-PE12-PF12-PG12-PI12-PK12 -> 0 | PM12: =PL12*H12 -> 0 | PN12: =(PC12+PD12+PE12+PF12+(PG12+((PH12*$F12)/$H12)+PK12))*$L12 -> 0 | PP12: =PO12-PL12 -> 0 | PQ12: =PL12 -> 0 | QB12: =(QA12*F12)/H12 -> 0 | QC12: =IF(E12=0,0,SUMIF('Cocktail (December 2025)'!$F$6:$DB$1547,E12,'Cocktail (December 2025)'!$CC$6:$CC$1547)) -> 0 | QD12: =QC12/H12 -> 0 | QE12: =PQ12+PR12+PS12+PT12-PU12-PV12-PW12-PX12-PY12-PZ12-QB12-QD12 -> 0 | QF12: =QE12*H12 -> 0 | QG12: =(PV12+PW12+PX12+PY12+(PZ12+((QA12*$F12)/$H12)+QD12))*$L12 -> 0 | QI12: =QH12-QE12 -> 0 | QJ12: =QE12 -> 0 | QU12: =(QT12*F12)/H12 -> 0 | QV12: =IF(E12=0,0,SUMIF('Cocktail (December 2025)'!$F$6:$DB$1547,E12,'Cocktail (December 2025)'!$CF$6:$CF$1547)) -> 0 | QW12: =QV12/H12 -> 0 | QX12: =QJ12+QK12+QL12+QM12-QN12-QO12-QP12-QQ12-QR12-QS12-QU12-QW12 -> 0 | QY12: =QX12*H12 -> 0 | QZ12: =(QO12+QP12+QQ12+QR12+(QS12+((QT12*$F12)/$H12)+QW12))*$L12 -> 0 | RB12: =RA12-QX12 -> 0 | RC12: =QX12 -> 0 | RN12: =(RM12*F12)/H12 -> 0 | RO12: =IF(E12=0,0,SUMIF('Cocktail (December 2025)'!$F$6:$DB$1547,E12,'Cocktail (December 2025)'!$CI$6:$CI$1547)) -> 0 | RP12: =RO12/H12 -> 0 | RQ12: =RC12+RD12+RE12+RF12-RG12-RH12-RI12-RJ12-RK12-RL12-RN12-RP12 -> 0 | RR12: =RQ12*H12 -> 0 | RS12: =(RH12+RI12+RJ12+RK12+(RL12+((RM12*$F12)/$H12)+RP12))*$L12 -> 0 | RU12: =RT12-RQ12 -> 0 | RV12: =RQ12 -> 0 | SG12: =(SF12*F12)/H12 -> 0 | SH12: =IF(E12=0,0,SUMIF('Cocktail (December 2025)'!$F$6:$DB$1547,E12,'Cocktail (December 2025)'!$CL$6:$CL$1547)) -> 0 | SI12: =SH12/H12 -> 0 | SJ12: =RV12+RW12+RX12+RY12-RZ12-SA12-SB12-SC12-SD12-SE12-SG12-SI12 -> 0 | SK12: =SJ12*H12 -> 0 | SL12: =(SA12+SB12+SC12+SD12+(SE12+((SF12*$F12)/$H12)+SI12))*$L12 -> 0 | SN12: =SM12-SJ12 -> 0 | SO12: =SJ12 -> 0 | SZ12: =(SY12*F12)/H12 -> 0 | TA12: =IF(E12=0,0,SUMIF('Cocktail (December 2025)'!$F$6:$DB$1547,E12,'Cocktail (December 2025)'!$CO$6:$CO$1547)) -> 0 | TB12: =TA12/H12 -> 0 | TC12: =SO12+SP12+SQ12+SR12-SS12-ST12-SU12-SV12-SW12-SX12-SZ12-TB12 -> 0 | TD12: =TC12*H12 -> 0 | TE12: =(ST12+SU12+SV12+SW12+(SX12+((SY12*$F12)/$H12)+TB12))*$L12 -> 0 | TG12: =TF12-TC12 -> 0 | TH12: =TC12 -> 0 | TS12: =(TR12*F12)/H12 -> 0 | TT12: =IF(E12=0,0,SUMIF('Cocktail (December 2025)'!$F$6:$DB$1547,E12,'Cocktail (December 2025)'!$CR$6:$CR$1547)) -> 0 | TU12: =TT12/H12 -> 0 | TV12: =TH12+TI12+TJ12+TK12-TL12-TM12-TN12-TO12-TP12-TQ12-TS12-TU12 -> 0 | TW12: =TV12*H12 -> 0 | TX12: =(TM12+TN12+TO12+TP12+(TQ12+((TR12*$F12)/$H12)+TU12))*$L12 -> 0 | TZ12: =TY12-TV12 -> 0 | UA12: =TV12 -> 0 | UL12: =(UK12*F12)/H12 -> 0 | UM12: =IF(E12=0,0,SUMIF('Cocktail (December 2025)'!$F$6:$DB$1547,E12,'Cocktail (December 2025)'!$CU$6:$CU$1547)) -> 0 | UN12: =UM12/H12 -> 0 | UO12: =UA12+UB12+UC12+UD12-UE12-UF12-UG12-UH12-UI12-UJ12-UL12-UN12 -> 0 | UP12: =UO12*H12 -> 0 | UQ12: =(UF12+UG12+UH12+UI12+(UJ12+((UK12*$F12)/$H12)+UN12))*$L12 -> 0 | US12: =UR12-UO12 -> 0 | UT12: =UO12 -> 0 | VE12: =(VD12*F12)/H12 -> 0 | VF12: =IF(E12=0,0,SUMIF('Cocktail (December 2025)'!$F$6:$DB$1547,E12,'Cocktail (December 2025)'!$CX$6:$CX$1547)) -> 0 | VG12: =VF12/H12 -> 0 | VH12: =UT12+UU12+UV12+UW12-UX12-UY12-UZ12-VA12-VB12-VC12-VE12-VG12 -> 0 | VI12: =VH12*H12 -> 0 | VJ12: =(UY12+UZ12+VA12+VB12+(VC12+((VD12*$F12)/$H12)+VG12))*$L12 -> 0 | VL12: =VK12-VH12 -> 0 | VM12: =VH12 -> 0 | VX12: =(VW12*F12)/H12 -> 0 | VY12: =IF(E12=0,0,SUMIF('Cocktail (December 2025)'!$F$6:$DB$1547,E12,'Cocktail (December 2025)'!$DA$6:$DA$1547)) -> 0 | VZ12: =VY12/H12 -> 0 | WA12: =VM12+VN12+VO12+VP12-VQ12-VR12-VS12-VT12-VU12-VV12-VX12-VZ12 -> 0 | WB12: =WA12*H12 -> 0 | WC12: =(VR12+VS12+VT12+VU12+(VV12+((VW12*$F12)/$H12)+VZ12))*$L12 -> 0 | WE12: =WD12-WA12 -> 0 | WF12: X | WG12: =O12 -> 0 | WH12: =P12+AI12+BB12+BU12+CN12+DG12+DZ12+ES12+FL12+GE12+GX12+HQ12+IJ12+JC12+JV12+KO12+LH12+MA12+MT12+NM12+OF12+OY12+PR12+QK12+RD12+RW12+SP12+TI12+UB12+UU12+VN12 -> 0 | WI12: =Q12+AJ12+BC12+BV12+CO12+DH12+EA12+ET12+FM12+GF12+GY12+HR12+IK12+JD12+JW12+KP12+LI12+MB12+MU12+NN12+OG12+OZ12+PS12+QL12+RE12+RX12+SQ12+TJ12+UC12+UV12+VO12 -> 0 | WJ12: =R12+AK12+BD12+BW12+CP12+DI12+EB12+EU12+FN12+GG12+GZ12+HS12+IL12+JE12+JX12+KQ12+LJ12+MC12+MV12+NO12+OH12+PA12+PT12+QM12+RF12+RY12+SR12+TK12+UD12+UW12+VP12 -> 0 | WK12: =S12+AL12+BE12+BX12+CQ12+DJ12+EC12+EV12+FO12+GH12+HA12+HT12+IM12+JF12+JY12+KR12+LK12+MD12+MW12+NP12+OI12+PB12+PU12+QN12+RG12+RZ12+SS12+TL12+UE12+UX12+VQ12 -> 0 | WL12: =T12+AM12+BF12+BY12+CR12+DK12+ED12+EW12+FP12+GI12+HB12+HU12+IN12+JG12+JZ12+KS12+LL12+ME12+MX12+NQ12+OJ12+PC12+PV12+QO12+RH12+SA12+ST12+TM12+UF12+UY12+VR12 -> 0 | WM12: =U12+AN12+BG12+BZ12+CS12+DL12+EE12++EX12+FQ12+GJ12+HC12+HV12+IO12+JH12+KA12+KT12+LM12+MF12+MY12+NR12+OK12+PD12+PW12+QP12+RI12+SB12+SU12+TN12+UG12+UZ12+VS12 -> 0 | WN12: =V12+AO12+BH12+CA12+CT12+DM12+EF12+EY12+FR12+GK12+HD12+HW12+IP12+JI12+KB12+KU12+LN12+MG12+MZ12+NS12+OL12+PE12+PX12+QQ12+RJ12+SC12+SV12+TO12+UH12+VA12+VT12 -> 0 | WO12: =W12+AP12+BI12+CB12+CU12+DN12+EG12+EZ12+FS12+GL12+HE12+HX12+IQ12+JJ12+KC12+KV12+LO12+MH12+NA12+NT12+OM12+PF12+PY12+QR12+RK12+SD12+SW12+TP12+UI12+VB12+VU12 -> 0 | WP12: =X12+AQ12+BJ12+CC12+CV12+DO12+EH12+FA12+FT12+GM12+HF12+HY12+IR12+JK12+KD12+KW12+LP12+MI12+NB12+NU12+ON12+PG12+PZ12+QS12+RL12+SE12+SX12+TQ12+UJ12+VC12+VV12 -> 0 | WQ12: =Y12+AR12+BK12+CD12+CW12+DP12+EI12+FB12+FU12+GN12+HG12+HZ12+IS12+JL12+KE12+KX12+LQ12+MJ12+NC12+NV12+OO12+PH12+QA12+QT12+RM12+SF12+SY12+TR12+UK12+VD12+VW12 -> 0 | WR12: =Z12+AS12+BL12+CE12+CX12+DQ12+EJ12+FC12+FV12+GO12+HH12+IA12+IT12+JM12+KF12+KY12+LR12+MK12+ND12+NW12+OP12+PI12+QB12+QU12+RN12+SG12+SZ12+TS12+UL12+VE12+VX12 -> 0 | WS12: =AB12+AU12+BN12+CG12+CZ12+DS12+EL12+FE12+FX12+GQ12+HJ12+IC12+IV12+JO12+KH12+LA12+LT12+MM12+NF12+NY12+OR12+PK12+QD12+QW12+RP12+SI12+TB12+TU12+UN12+VG12+VZ12 -> 0 | WT12: =WA12 -> 0 | WU12: =WB12 -> 0 | WW12: =WV12-WT12 -> 0 | WX12: =WV12/F12 -> 0
